Workbook

Sheet Summary
A1: FlashKa Keychain v0.7 - what it really costs
A2: Complete cost of building the light from scratch: electronics (one JLCPCB panel: main PCB + key board), housing (JLCCNC: aluminium tray + lid, a PMMA kit with the main keys, a POM-C kit; JLC3DP, in the same order: the resin casting mould for the rubber side keys, once per builder), bought parts (the 14500 cell, LED board, TIR optic, laser, screws), consumables (including the nickel strip and the casting supplies), shipping, EU VAT and customs for Lithuania. Scenario A = you build ONE light (JLCPCB still sells 5 bare panels and assembles at least 2), scenario B = you build FIVE (type 2 in B to see two lights). Prices that did not change keep the date they were read (2026-10-14 for v0.5, 2026-10-18 for v0.6, 2026-10-21 for the first v0.7 layout); the parts of the 1000 lm power stage were read on 2026-10-22, the cell, the nickel strip and R3 on 2026-10-23. Blue on amber cells are ESTIMATES because the shop shows its price only after you upload the files (or no listing was read) - replace them with the real quote.
A3: Colour code: blue = typed-in number, blue on amber = ESTIMATE, black = formula, green = taken from another sheet. USD is the main currency, EUR = USD / rate.
A5: Inputs
A6: Exchange rate (USD per EUR) | B6: 1.1188 | C6: USD per EUR | D6: ECB euro reference rate of 13 Oct 2026 (not refreshed since v0.5). Change it to the rate of your bank/card. Source: https://www.ecb.europa.eu/stats/policy_and_exchange_rates/euro_reference_exchange_rates/html/eurofxref-graph-usd.en.html (read 2026-10-13)
A7: Scenario A: lights you build | B7: 1 | C7: lights | D7: Scenario A: you build one light.
A8: Scenario B: lights you build | B8: 5 | C8: lights | D8: Scenario B: you build five lights (all JLC minimums are used up). Type 2 to see two lights.
A9: Price check date (v0.7) | B9: 2026-10-23 | C9: One-cell layout (2026-10-23): the Vapcell F15 cell and the nickel strip (nkon.nl), R3 (C4109, LCSC) and the Vapcell K10 (illumn.com) were read on this date; nkon's shipping rate could not be read (ESTIMATE). 1000 lm power stage (2026-10-22): the buck TPS62095 and the protection IC DW01A (LCSC), the LED board, the TIR optic, the ECON 80 urethane, Sugru, JLC3DP's resin rate, JLCCNC's merged ordering and the EU customs rules; the page of the MOSFET SE8830A could not be read (ESTIMATE). First v0.7 check (2026-10-21): the pogo pin, the JLCPCB panel fee for two designs, JLCCNC's minimum size for plastic parts. Prices and fees that did not change keep the date they were read: 2026-10-14 (v0.5 check; LCSC and JLC pages) and 2026-10-18 (v0.6; the pages of C115357 and C25104 could not be read, those lines are ESTIMATES). Re-check before ordering.
A11: Total cost
A12: Cost group | B12: A: total (USD) | C12: A: total (EUR) | D12: A: per light (USD) | E12: A: per light (EUR) | F12: B: total (USD) | G12: B: total (EUR) | H12: B: per light (USD) | I12: B: per light (EUR) | J12: Share of B | K12: Basis
A13: Lights built | B13: =$B$7 -> 1 | F13: =$B$8 -> 5
A14: 1. PCB + assembly (JLCPCB, one panel: main PCB + key board) | B14: ='JLCPCB order'!$E$81 -> 236.89618 | C14: =B14/$B$6 -> 211.74131 | D14: =B14/$B$7 -> 236.89618 | E14: =D14/$B$6 -> 211.74131 | F14: ='JLCPCB order'!$G$81 -> 282.06529 | G14: =F14/$B$6 -> 252.11413 | H14: =F14/$B$8 -> 56.413059 | I14: =H14/$B$6 -> 50.422827 | J14: =F14/F32 -> 0.18850215 | K14: Fees: JLCPCB price page, read 2026-10-14, main rates and the panel fee re-read 2026-10-21. Parts: LCSC prices read 2026-10-14, the pogo pin 2026-10-21, the buck and the protection IC 2026-10-22, R3 2026-10-23; C238645, C25104, C115357 are ESTIMATES. Bare panels and the two-design surcharge: ESTIMATES.
A15: of which bare panels + two-design surcharge (4 layers, 0.8 mm, ENIG, black solder mask) | B15: ='JLCPCB order'!$E$49+'JLCPCB order'!$E$50 -> 45 | C15: =B15/$B$6 -> 40.221666 | D15: =B15/$B$7 -> 45 | E15: =D15/$B$6 -> 40.221666 | F15: ='JLCPCB order'!$G$49+'JLCPCB order'!$G$50 -> 45 | G15: =F15/$B$6 -> 40.221666 | H15: =F15/$B$8 -> 9 | I15: =H15/$B$6 -> 8.0443332 | K15: ESTIMATE - the price appears only after the Gerber upload.
A16: of which assembly fees (set-up, stencil, joints, feeder, panel fee, X-ray, ...) | B16: ='JLCPCB order'!$E$72 -> 145.14528 | C16: =B16/$B$6 -> 129.733 | D16: =B16/$B$7 -> 145.14528 | E16: =D16/$B$6 -> 129.733 | F16: ='JLCPCB order'!$G$72 -> 151.08819 | G16: =F16/$B$6 -> 135.04486 | H16: =F16/$B$8 -> 30.217639 | I16: =H16/$B$6 -> 27.008973 | K16: JLCPCB fee page, sheet 'JLCPCB order'.
A17: of which components (35 lines, 79 parts per panel, incl. spares for placement loss) | B17: ='Panel BOM'!$T$44 -> 46.7509 | C17: =B17/$B$6 -> 41.786646 | D17: =B17/$B$7 -> 46.7509 | E17: =D17/$B$6 -> 41.786646 | F17: ='Panel BOM'!$W$44 -> 85.9771 | G17: =F17/$B$6 -> 76.847605 | H17: =F17/$B$8 -> 17.19542 | I17: =H17/$B$6 -> 15.369521 | K17: LCSC price tiers, sheet 'Panel BOM'.
A18: 2. Housing (JLCCNC + JLC3DP: aluminium tray + lid, PMMA and POM-C kits, resin casting mould) | B18: =Housing!$B$129 -> 132.90562 | C18: =B18/$B$6 -> 118.79301 | D18: =B18/$B$7 -> 132.90562 | E18: =D18/$B$6 -> 118.79301 | F18: =Housing!$C$129 -> 432.50404 | G18: =F18/$B$6 -> 386.57851 | H18: =F18/$B$8 -> 86.500807 | I18: =H18/$B$6 -> 77.315702 | J18: =F18/F32 -> 0.28903924 | K18: ESTIMATE - replace by the JLCCNC and JLC3DP instant quotes.
A19: of which aluminium tray + lid (bead blast + black anodize, no marking) | B19: =Housing!$B$96 -> 98.337105 | C19: =B19/$B$6 -> 87.89516 | D19: =B19/$B$7 -> 98.337105 | E19: =D19/$B$6 -> 87.89516 | F19: =Housing!$C$96 -> 347.68553 | G19: =F19/$B$6 -> 310.76647 | H19: =F19/$B$8 -> 69.537105 | I19: =H19/$B$6 -> 62.153294 | K19: ESTIMATE from volume, box, fine features and finish, sheet 'Housing' sections 2-6 (the panel texture included: 'texture_on').
A20: of which PMMA kit (main keys) + POM-C kit (RF insert, antenna spacer) | B20: =Housing!$E$122 -> 31.25 | C20: =B20/$B$6 -> 27.931713 | D20: =B20/$B$7 -> 31.25 | E20: =D20/$B$6 -> 27.931713 | F20: =Housing!$G$122 -> 81.5 | G20: =F20/$B$6 -> 72.845906 | H20: =F20/$B$8 -> 16.3 | I20: =H20/$B$6 -> 14.569181 | K20: ESTIMATE - JLCCNC publishes no price for plastic parts; sheet 'Housing' section 7.
A21: of which resin casting mould for the rubber side keys (two SLA plates, JLC3DP, once per builder) | B21: =Housing!$B$110 -> 3.31851 | C21: =B21/$B$6 -> 2.9661334 | D21: =B21/$B$7 -> 3.31851 | E21: =D21/$B$6 -> 2.9661334 | F21: =Housing!$C$110 -> 3.31851 | G21: =F21/$B$6 -> 2.9661334 | H21: =F21/$B$8 -> 0.663702 | I21: =H21/$B$6 -> 0.59322667 | K21: ESTIMATE from JLC3DP's headline rate, sheet 'Housing' section 6b. Leave it out if you already have a mould.
A22: 3. Bought parts (the cell, LED board, TIR optic, laser, screws, set screw, split ring, mould hardware) | B22: ='Bought parts'!$L$31 -> 65.79 | C22: =B22/$B$6 -> 58.804076 | D22: =B22/$B$7 -> 65.79 | E22: =D22/$B$6 -> 58.804076 | F22: ='Bought parts'!$N$31 -> 203 | G22: =F22/$B$6 -> 181.4444 | H22: =F22/$B$8 -> 40.6 | I22: =H22/$B$6 -> 36.288881 | J22: =F22/F32 -> 0.1356634 | K22: The cell, the LED board and the optic READ; the rest typical prices (ESTIMATES), sheet 'Bought parts'.
A23: 4. Consumables (nickel strip, wire, thermal paste, tapes, foam, silicone pads, adhesives, casting supplies) | B23: ='Bought parts'!$L$32 -> 115.53 | C23: =B23/$B$6 -> 103.26242 | D23: =B23/$B$7 -> 115.53 | E23: =D23/$B$6 -> 103.26242 | F23: ='Bought parts'!$N$32 -> 115.53 | G23: =F23/$B$6 -> 103.26242 | H23: =F23/$B$8 -> 23.106 | I23: =H23/$B$6 -> 20.652485 | J23: =F23/F32 -> 0.077207843 | K23: Typical prices (ESTIMATES); the nickel strip read at nkon.nl, the urethane rubber at kaupo.de. Sheet 'Bought parts'.
A24: of which casting supplies for the side keys (urethane, pigment, release, shim, glue, cups, polishes) | B24: ='Bought parts'!$L$37 -> 85.95 | C24: =B24/$B$6 -> 76.823382 | D24: =B24/$B$7 -> 85.95 | E24: =D24/$B$6 -> 76.823382 | F24: ='Bought parts'!$N$37 -> 85.95 | G24: =F24/$B$6 -> 76.823382 | H24: =F24/$B$8 -> 17.19 | I24: =H24/$B$6 -> 15.364676 | K24: Once per builder; one unit of rubber casts many keys.
A25: 5. Shipping, VAT, customs duty, carrier and bank fees | B25: ='Hidden costs'!$J$45 -> 308.16073 | C25: =B25/$B$6 -> 275.43862 | D25: =B25/$B$7 -> 308.16073 | E25: =D25/$B$6 -> 275.43862 | F25: ='Hidden costs'!$J$57 -> 463.25124 | G25: =F25/$B$6 -> 414.06082 | H25: =F25/$B$8 -> 92.650249 | I25: =H25/$B$6 -> 82.812164 | J25: =F25/F32 -> 0.30958737 | K25: Computed from EU rules and shipping ESTIMATES, sheet 'Hidden costs'.
A26: of which shipping (JLCPCB, JLCCNC + JLC3DP, the EU casting shop, the optic distributor, the battery shop, web-shop parcels) | B26: ='Hidden costs'!$F$43 -> 110.93 | C26: =B26/$B$6 -> 99.150876 | D26: =B26/$B$7 -> 110.93 | E26: =D26/$B$6 -> 99.150876 | F26: ='Hidden costs'!$F$55 -> 113.93 | G26: =F26/$B$6 -> 101.83232 | H26: =F26/$B$8 -> 22.786 | I26: =H26/$B$6 -> 20.366464 | K26: Shipping per parcel are ESTIMATES (JLC shows them in the cart).
A27: of which VAT 21 % | B27: ='Hidden costs'!$H$43 -> 139.03088 | C27: =B27/$B$6 -> 124.26786 | D27: =B27/$B$7 -> 139.03088 | E27: =D27/$B$6 -> 124.26786 | F27: ='Hidden costs'!$H$55 -> 246.64071 | G27: =F27/$B$6 -> 220.45112 | H27: =F27/$B$8 -> 49.328142 | I27: =H27/$B$6 -> 44.090224 | K27: Lithuania 21 %, collected by JLC at checkout up to EUR 150 per parcel.
A28: of which customs duty and carrier fees | B28: ='Hidden costs'!$G$43+'Hidden costs'!$I$43 -> 50.346 | C28: =B28/$B$6 -> 45 | D28: =B28/$B$7 -> 50.346 | E28: =D28/$B$6 -> 45 | F28: ='Hidden costs'!$G$55+'Hidden costs'!$I$55 -> 87.865442 | G28: =F28/$B$6 -> 78.535433 | H28: =F28/$B$8 -> 17.573088 | I28: =H28/$B$6 -> 15.707087 | K28: Flat EUR 3 per customs line up to EUR 150 per parcel; formal clearance + carrier fee above.
A29: of which card / currency conversion fee | B29: ='Hidden costs'!$J$44 -> 7.8538495 | C29: =B29/$B$6 -> 7.019887 | D29: =B29/$B$7 -> 7.8538495 | E29: =D29/$B$6 -> 7.019887 | F29: ='Hidden costs'!$J$56 -> 14.81509 | G29: =F29/$B$6 -> 13.241947 | H29: =F29/$B$8 -> 2.963018 | I29: =H29/$B$6 -> 2.6483894 | K29: ESTIMATE 1.5 % on the USD payments to JLC.
A30: JLCPCB order vs the EUR 150 IOSS line (EUR left; negative = above, formal customs) | B30: ='JLCPCB order'!$E$83 -> -61.74131 | F30: ='JLCPCB order'!$G$83 -> -102.11413 | G30: Above the line the parcel pays a carrier fee of about EUR 15 (sheet 'Hidden costs', sections 4-6).
A31: JLCCNC + JLC3DP order vs the EUR 150 IOSS line (EUR left; negative = above, formal customs) | B31: =Housing!$B$128 -> 31.206994 | F31: =Housing!$C$128 -> -236.57851 | G31: One light: below the line (VAT and EUR 3 per customs line only). More lights: above it (6 % duty, VAT and a carrier fee).
A32: TOTAL for the lights (1 + 2 + 3 + 4 + 5) | B32: =B14+B18+B22+B23+B25 -> 859.28252 | C32: =B32/$B$6 -> 768.03943 | D32: =B32/$B$7 -> 859.28252 | E32: =D32/$B$6 -> 768.03943 | F32: =F14+F18+F22+F23+F25 -> 1496.3506 | G32: =F32/$B$6 -> 1337.4603 | H32: =F32/$B$8 -> 299.27011 | I32: =H32/$B$6 -> 267.49206 | K32: Per-light columns divide by the number of lights built.
A33: Extra cost of each additional light (scenario B vs A) | B33: =IF($B$8=$B$7,0,(F32-B32)/($B$8-$B$7)) -> 159.26701 | C33: =B33/$B$6 -> 142.35521 | D33: Set-up fees, stencil, panel fee, feeder loading, the anodizing lot fee, the casting mould, the casting supplies and most shipping are paid once, so the 2nd to 5th light is much cheaper than the first.
A35: What changed since the first v0.7 layout (same scenarios and exchange rate; USD)
A36: The 'first layout' values are typed in from the cost workbook of the first v0.7 layout (price check 2026-10-21: SST-20 behind a glass window, 2 x 400 mAh cells with protection boards, a 3 A buck, the aluminium casting mould, PMC-780 DRY rubber; 1 light in A, 5 in B). Since then the light got the parts for 1000 lm and 100 m (TIR optic, 4 A buck with board protection, 24 AWG wire), one 14500 cell in an octagonal body, and cost was taken out where it does not hurt the design. A negative change is a saving. docs/bom_notes.md has the same table for 1, 2 and 5 lights.
A37: Cost group | B37: First layout: A | C37: Now: A | D37: Change A | E37: First layout: B | F37: Now: B | G37: Change B | H37: What changed (savings, new costs, quality)
A38: 1. PCB + assembly (JLCPCB) | B38: 228.66 | C38: =B14 -> 236.89618 | D38: =C38-B38 -> 8.2361775 | E38: 269.12 | F38: =F14 -> 282.06529 | G38: =F38-E38 -> 12.945294 | H38: No saving here: the 1000 lm power stage is new. The 4 A buck TPS62095 costs $1.35 per board (the TLV62585 it replaces cost $0.26), the protection IC DW01A $0.03 and the dual MOSFET SE8830A $0.10 (ESTIMATE), plus five small parts; U2 is a QFN, so X-ray counts 4 parts per panel instead of 3 ($13.12 instead of $9.84 for 2 panels). The cheaper pogo pin is an option (table below).
A39: 2. Housing | B39: 169.16 | C39: =B18 -> 132.90562 | D39: =C39-B39 -> -36.254385 | E39: 473.59 | F39: =F18 -> 432.50404 | G39: =F39-E39 -> -41.085963 | H39: Resin casting mould from JLC3DP ($3.32, ESTIMATE) instead of the aluminium mould ($35.12): $31.80 less, once per builder. The POM-C kit lost the LED spacer ring (one part type less: $31.25 instead of $37.75 for the kits). The body is 4.8 mm longer (for the optic and the cell) and an octagon 20 x 18 mm instead of a 20 x 16 mm rectangle (tray + lid $98.34 instead of $96.29). Quality: the resin print does not hold the aluminium mould's +/-0.02 mm (try the first key in its opening) and wears out sooner; the aluminium mould stays an option.
A40: 3. Bought parts | B40: 63.75 | C40: =B22 -> 65.79 | D40: =C40-B40 -> 2.04 | E40: 218.3 | F40: =F22 -> 203 | G40: =F40-E40 -> -15.3 | H40: LED board $2.99 instead of $5.40 (SST-20 Gen 2, Kaidomain, read); no glass window ($2.95 per 5). New: the TIR optic ($17.37 per pack of 5); one 14500 cell (Vapcell F15, $3.47 at nkon.nl, read) instead of two 400 mAh cells with protection boards ($4.50 each); the resin mould's bolts, washers and nuts ($4.00) instead of the aluminium mould's dowel pins and screws ($5.00).
A41: 4. Consumables | B41: 142.19 | C41: =B23 -> 115.53 | D41: =C41-B41 -> -26.66 | E41: 142.19 | F41: =F23 -> 115.53 | G41: =F41-E41 -> -26.66 | H41: ECON 80 urethane ($31.95 for 0.86 kg) instead of PMC-780 DRY ($60.40 for 1.36 kg): the same Shore 80A, mixed 1:1 by volume, so the 0.01 g scale is no longer needed; casting supplies $85.95 instead of $114.40. Thermal paste instead of thermal tape, 24 AWG wire for the 3 A paths, nickel strip for the cell ($2.08 per metre), 0.5 mm foam sheet. Quality: none - ECON 80 meets the 75-85 Shore A of the drawing; its pot life is 13 minutes instead of 25 (pour without delay).
A42: 5. Shipping, VAT, customs, fees | B42: 315.13 | C42: =B25 -> 308.16073 | D42: =C42-B42 -> -6.969274 | E42: 452.61 | F42: =F25 -> 463.25124 | G42: =F42-E42 -> 10.641243 | H42: The merged JLCCNC + JLC3DP order of one light is EUR 118.79, below the EUR 150 line (the first layout: EUR 151.20 with the aluminium mould, so 6 % duty, VAT and a carrier fee of about EUR 15); 8 web-shop parcels instead of 10 (no glass window; the cell comes from an EU shop). New: the optic distributor's parcel and the battery shop's parcel (ESTIMATE $20.00 and $13.43 shipping, VAT only). Duty and carrier fees $50.35 instead of $78.60, VAT $139.03 instead of $146.31, shipping $110.93 instead of $81.50.
A43: TOTAL for the lights | B43: 918.89 | C43: =B32 -> 859.28252 | D43: =C43-B43 -> -59.607481 | E43: 1555.81 | F43: =F32 -> 1496.3506 | G43: =F43-E43 -> -59.459427 | H43: Sum of the lines above.
...

Sheet JLCPCB order
A1: JLCPCB order - one panel (key board + main PCB), bare panels + Standard PCBA (parts on both faces)
A2: What you order at jlcpcb.com in ONE order: 5 bare 4-layer panels (each holds the key board and the main PCB, black solder mask) and the assembly (soldering of all SMD parts) of 2 or 5 of them. Column E = scenario A (you build 1 light), column G = scenario B (you build 5 lights). Every fee is a blue input with the date it was read and its URL: the fee page says 'Last updated on Sep 09, 2026'; it was read on 2026-10-14 and its main rates were checked again on 2026-10-21 (the panel fee for two designs was read then). Prices change - re-check before you pay.
A3: Colour code: blue = typed-in number, blue on amber = ESTIMATE (no public price), black = formula, green = taken from another sheet.
A5: 1. What to select in the JLCPCB cart (https://cart.jlcpcb.com/quote)
A6: Setting | B6: Value | E6: Why / what to watch
A7: Base material / layers | B7: FR-4, 4 layers | E7: Both boards use the same 4-layer stack-up with an inner ground plane. Do not change the layer count.
A8: Dimensions | B8: 45.0 x 32.5 mm (JLC reads it from the Gerber) | E8: One panel: key board left, main PCB right, two 6 mm rails with 3 fiducials and 4 tooling holes (section 2).
A9: PCB quantity | B9: 5 | E9: JLCPCB minimum. Four spare panels cost little and cover first-article problems.
A10: Delivery format / panel format | B10: Panel by Customer, 1 x 1 | E10: The Gerber already is the panel; do not let JLCPCB panelise it again.
A11: Different design | B11: 2 | E11: Two different boards in one file: JLCPCB adds a surcharge, shown after the upload (section 4, ESTIMATE).
A12: PCB thickness | B12: 0.8 mm | E12: The housing is built around 0.8 mm boards (main PCB on its ledges, key board on its bosses).
A13: Surface finish | B13: ENIG (immersion gold) | E13: Flat pads for the module and the fine-pitch parts, and gold pads J6 under the pogo pins.
A14: Solder mask / silkscreen | B14: BLACK solder mask, WHITE silkscreen | E14: The design and all renders use black boards. A colour surcharge, if the cart shows one, belongs to the bare-panel price.
A15: Copper / via covering | B15: 1 oz outer, 0.5 oz inner; tented vias | E15: Defaults; the board is designed for them. Option: inner copper 1 oz (a small surcharge in the quote) halves the resistance of the 2 mm battery strip inside the board.
A16: Edge rails / fiducials | B16: by customer (on the rails) | E16: If JLCPCB's review asks for a bigger panel for Standard assembly (it names 70 x 70 mm as the smallest), accept the edge rails it offers.
A17: Order number on the board | B17: Default (JLC prints a code in a free area) | E17: Removing the code costs extra; it stays inside the closed body.
... A24: Shipping | B24: Your choice (see sheet 'Hidden costs') | E24: Choose DDP / 'taxes paid' so the VAT is collected at checkout and nothing is asked at your door.
A26: 2. The panel and the two boards (mm)
A27: Panel width (mm) | B27: 45 | C27: tools/kicad/panel_jlc.py: key board left, main PCB right, 2.0 mm routed gaps, 6 mm rails top and bottom; the Gerber job file gives 45.1 x 32.6 mm (the 0.1 mm outline stroke included).
A28: Panel height (mm) | B28: 32.5
A29: Panel area (cm2) | B29: =B27*B28/100 -> 14.625 | C29: Only feeds the tiny packing fee. JLCPCB measures the Gerber itself. The panel stays inside the cheapest 4-layer size class (up to 50 x 50 mm).
A30: Main PCB (information) | B30: 24.0 x 16.5 mm, two corners chamfered 1.3 mm, 3.94 cm2 (housing_interface.json 'pcb_outline'); unchanged from v0.6.
A31: Key board (information) | B31: 19.0 x 14.8 mm, corners R1.0, 0.8 mm, 4 layers: switches and ring LEDs on the bottom face, six pogo pins and eight resistors on the top face.
A33: 3. Quantities (JLCPCB minimums: 5 bare panels, assembly from 2 panels)
A34: Minimum panels JLCPCB assembles | B34: 2 | C34: panels | D34: JLCPCB assembles from 2 boards; one light therefore still pays for 2 assembled panels (1 spare). The 'board' JLCPCB counts is the panel: key board + main PCB. Source: https://jlcpcb.com/pcb-assembly (read 2026-10-14)
A35: Minimum bare panels per design | B35: 5 | C35: panels | D35: JLCPCB sells at least 5 bare boards (here: panels) per design. Source: https://cart.jlcpcb.com/quote (read 2026-10-14)
A36: Assembled sides (double-sided) | B36: 2 | C36: sides | D36: Parts are on both faces of both boards = double-sided Standard PCBA (Economic PCBA is single-sided only).
A37: X-ray inspected parts per panel (optional) | B37: 4 | C37: parts per panel | D37: Fee page: 'X-ray inspection is required for components such as BGA, QFN and other leadless packages', charged per component. The COUNT is an assumption: U4 (ESP32 module, pads under it) and U2 (the buck TPS62095, a QFN without leads, new with the 1000 lm power stage) on the main PCB, LED3 and LED4 (pads under the package) on the key board = 4 per panel. Set 0 if your cart does not ask for it. Source: https://jlcpcb.com/help/article/pcb-assembly-price (read 2026-10-22)
E38: Scenario A | G38: Scenario B
A39: Lights you build | E39: =Summary!$B$7 -> 1 | G39: =Summary!$B$8 -> 5
A40: Panels assembled by JLCPCB = MAX(lights, minimum) | E40: =MAX(E39,$B$34) -> 2 | G40: =MAX(G39,$B$34) -> 5
A41: Bare panels ordered (sold in steps of 5) | E41: =CEILING(MAX($B$35,E40),5) -> 5 | G41: =CEILING(MAX($B$35,G40),5) -> 5
A43: 4. Bare panel fabrication (4 layers, 0.8 mm, ENIG, black solder mask, 45.0 x 32.5 mm) - shown by JLCPCB only AFTER the Gerber upload
A44: Bare panels, price for 5 (ESTIMATE) | B44: 30 | C44: USD for 5 panels | D44: ESTIMATE ($25-35 for 5): bare panels 45.0 x 32.5 mm, 4 layers, 0.8 mm, ENIG, black solder mask, white silkscreen. JLCPCB shows the price only after the Gerber upload (v0.6 estimated $25 for five 24 x 16.5 mm main PCBs). A colour surcharge, if the cart shows one, belongs here. Source: https://cart.jlcpcb.com/quote (read 2026-10-21)
A45: low end of the range (information) | B45: 25 | C45: USD for 5 panels | D45: ESTIMATE. Low end of the estimate range (information only). (2026-10-21)
A46: high end of the range (information) | B46: 35 | C46: USD for 5 panels | D46: ESTIMATE. High end of the estimate range (information only). (2026-10-21)
A47: Surcharge for two designs in one file (ESTIMATE) | B47: 15 | C47: USD per order | D47: ESTIMATE ($10-20): JLCPCB charges extra for more than one design in one Gerber file ('different design' fee, order option 'Different Design: 2'); the amount appears only in the calculator after the upload. Source: https://jlcpcb.com/help/article/In-what-cases-will-there-be-charged-extra (read 2026-10-21)
A48: Anchors: a 100 x 100 mm 4-layer board costs about $32.90 for 5 (https://pcbsync.com/pcb-prototype-services-compared/, 2026); a forum guide puts ENIG at +$5-10 on small orders (https://zbotic.in/how-to-order-pcb-from-jlcpcb-and-pcbway-india-cost-guide/); v0.6 estimated $25 for 5 single main PCBs. The 'different design' fee exists on JLCPCB's panelisation pages (https://jlcpcb.com/help/article/96-PCB-Panelization) but its amount appears only in the calculator. Real price: upload order_files/1_JLCPCB/FlashKa_panel_gerbers.zip at https://cart.jlcpcb.com/quote, choose the options of section 1 and type the prices shown into the two amber cells above.
A49: Bare panel cost (price for 5 x panels ordered / 5) | E49: =$B$44*$E$41/5 -> 30 | G49: =$B$44*$G$41/5 -> 30
A50: Two-design surcharge (once per order) | E50: =$B$47 -> 15 | G50: =$B$47 -> 15
...

Sheet Panel BOM
A1: Panel bill of materials - what JLCPCB assembles on the two boards (main PCB + key board)
A2: One line per component type (grouped by LCSC number), derived from tools/kicad/flashka_parts.py with the same grouping and ordering as tools/kicad/build_all.py, which writes the BOM you upload as order_files/1_JLCPCB/BOM_JLCPCB.csv: 35 lines, 79 placements, 267 solder joints per panel. Wire pads (J2 cell, J3 LED, J5 laser), the pogo target pads J6 and the key board's screw holes H1, H2 have no LCSC number: they are NOT assembled. The LED board, the TIR optic, the 14500 cell and the laser are bought parts (sheet 'Bought parts'). New in v0.7: the six pogo pins P1-P6 (Harwin P70-1010045R); SW1-SW3, LED3, LED4 and eight resistors moved from the main PCB to the key board, which JLCPCB makes in the same panel; the 1000 lm power stage added the 4 A buck TPS62095 (U2), the cell protection DW01A (U6) with the dual MOSFET SE8830A (Q3) and five small parts; for the 14500 cell R3 is 2.0 k (C4109) instead of 3.3 k, so the charger gives about 494 mA instead of 280 mA.
A3: Unit price = the LCSC price tier that matches the quantity JLCPCB has to buy = (quantity per panel x panels assembled) + extra pieces for placement loss (columns P-Q). Prices were read from the LCSC product pages on 2026-10-14 (v0.5 price check; the lines that did not change keep that date), for the pogo pin C22100007 on 2026-10-21, for the buck C139643 and the protection IC C351410 on 2026-10-22 and for R3 (C4109) on 2026-10-23 (columns X-AI hold the tier tables, typed in from the page). The three lines whose pages could not be read (C115357 and C25104 on 2026-10-18, C238645 on 2026-10-22) are blue on amber = ESTIMATE: tiers from the parts named in the 'Price source' column. JLC buys from LCSC/its own warehouse; the real component price shows in the JLC cart after the BOM upload.
A4: Basic / Extended = JLCPCB library type read on jlcpcb.com/partdetail/<LCSC number> on 2026-10-14 (assumed, amber, for four lines: Extended for C115357, C22100007 and C238645, Basic for C25104 - check them in the JLC BOM upload). In 2026 Standard PCBA every unique part costs the same feeder fee, Basic or Extended (see sheet 'JLCPCB order'); the 'Preferred' tag (only relevant for the single-sided Economic PCBA) was not shown on any of these pages. 'LCSC stock' is LCSC's retail stock, NOT JLC's warehouse; JLC flags real shortages when you upload the BOM.
B5: Panels assembled, scenario A | C5: ='JLCPCB order'!$E$40 -> 2
B6: Panels assembled, scenario B | C6: ='JLCPCB order'!$G$40 -> 5
A8: # | B8: Designators | C8: Value | D8: Footprint | E8: LCSC # | F8: Manufacturer part no. | G8: Manufacturer | H8: Description (flashka_parts.py) | I8: What it does (and on which board) | J8: Qty / panel | K8: Solder joints / part | L8: JLC part type | M8: JLC part page | N8: LCSC stock (retail) | O8: Stock note | P8: Loss class | Q8: Extra pcs | R8: Buy qty A | S8: Unit USD A | T8: Line USD A | U8: Buy qty B | V8: Unit USD B | W8: Line USD B | X8: Tier 1 from qty | Y8: Tier 2 from qty | Z8: Tier 3 from qty | AA8: Tier 4 from qty | AB8: Tier 5 from qty | AC8: Tier 6 from qty | AD8: Tier 1 USD | AE8: Tier 2 USD | AF8: Tier 3 USD | AG8: Tier 4 USD | AH8: Tier 5 USD | AI8: Tier 6 USD | AJ8: Price source
A9: 1 | B9: C1 | C9: 10uF | D9: C_0805_2012Metric | E9: C15850 | F9: CL21A106KAYNNNE | G9: Samsung Electro-Mechanics | H9: 10uF 25V X5R 0805 | I9: Smoothing capacitor on the USB 5 V input (25 V rating needed). Main PCB. | J9: =LEN(B9)-LEN(SUBSTITUTE(B9,",",""))+1 -> 1 | K9: 2 | L9: Basic | M9: JLC page | N9: 20 | O9: LOW: only 20 pcs at LCSC retail; JLC's own stock is separate - the BOM upload flags a shortage. Any 10 uF 25 V X5R 0805 Basic part is a substitute. | P9: p0603 | Q9: =INDEX($C$53:$C$56,MATCH(P9,$B$53:$B$56,0)) -> 5 | R9: =J9*$C$5+Q9 -> 7 | S9: =INDEX($AD9:$AI9,MAX(1,COUNTIF($X9:$AC9,"<="&R9))) -> 0.0695 | T9: =R9*S9 -> 0.4865 | U9: =J9*$C$6+Q9 -> 10 | V9: =INDEX($AD9:$AI9,MAX(1,COUNTIF($X9:$AC9,"<="&U9))) -> 0.0695 | W9: =U9*V9 -> 0.695 | X9: 20 | Y9: 200 | Z9: 600 | AA9: 2000 | AB9: 10000 | AC9: 20000 | AD9: 0.0695 | AE9: 0.0513 | AF9: 0.0419 | AG9: 0.0342 | AH9: 0.0315 | AI9: 0.0297 | AJ9: https://www.lcsc.com/product-detail/C15850.html (read 2026-10-14)
A10: 2 | B10: C2,C13,C15 | C10: 10uF | D10: C_0603_1608Metric | E10: C19702 | F10: CL10A106KP8NNNC | G10: Samsung Electro-Mechanics | H10: 10uF 10V X5R 0603 | I10: 10 uF capacitors that smooth the supply next to the chips (C2, C13, C15). Main PCB. | J10: =LEN(B10)-LEN(SUBSTITUTE(B10,",",""))+1 -> 3 | K10: 2 | L10: Basic | M10: JLC page | N10: 181020 | O10: OK | P10: p0603 | Q10: =INDEX($C$53:$C$56,MATCH(P10,$B$53:$B$56,0)) -> 5 | R10: =J10*$C$5+Q10 -> 11 | S10: =INDEX($AD10:$AI10,MAX(1,COUNTIF($X10:$AC10,"<="&R10))) -> 0.0311 | T10: =R10*S10 -> 0.3421 | U10: =J10*$C$6+Q10 -> 20 | V10: =INDEX($AD10:$AI10,MAX(1,COUNTIF($X10:$AC10,"<="&U10))) -> 0.0311 | W10: =U10*V10 -> 0.622 | X10: 20 | Y10: 200 | Z10: 600 | AA10: 4000 | AB10: 8000 | AC10: 20000 | AD10: 0.0311 | AE10: 0.023 | AF10: 0.0195 | AG10: 0.0168 | AH10: 0.0157 | AI10: 0.015 | AJ10: https://www.lcsc.com/product-detail/C19702.html (read 2026-10-14)
A11: 3 | B11: C5,C8,C22 | C11: 22uF | D11: C_0603_1608Metric | E11: C59461 | F11: CL10A226MQ8NRNC | G11: Samsung Electro-Mechanics | H11: 22uF 6.3V X5R 0603 | I11: 22 uF capacitors for the buck converter / power rails (C5, C8, C22). Main PCB. | J11: =LEN(B11)-LEN(SUBSTITUTE(B11,",",""))+1 -> 3 | K11: 2 | L11: Basic | M11: JLC page | N11: 4416440 | O11: OK | P11: p0603 | Q11: =INDEX($C$53:$C$56,MATCH(P11,$B$53:$B$56,0)) -> 5 | R11: =J11*$C$5+Q11 -> 11 | S11: =INDEX($AD11:$AI11,MAX(1,COUNTIF($X11:$AC11,"<="&R11))) -> 0.0315 | T11: =R11*S11 -> 0.3465 | U11: =J11*$C$6+Q11 -> 20 | V11: =INDEX($AD11:$AI11,MAX(1,COUNTIF($X11:$AC11,"<="&U11))) -> 0.0315 | W11: =U11*V11 -> 0.63 | X11: 20 | Y11: 200 | Z11: 600 | AA11: 4000 | AB11: 8000 | AC11: 20000 | AD11: 0.0315 | AE11: 0.0236 | AF11: 0.0201 | AG11: 0.0174 | AH11: 0.0164 | AI11: 0.0157 | AJ11: https://www.lcsc.com/product-detail/C59461.html (read 2026-10-14)
A12: 4 | B12: C12,C14,C17,C18 | C12: 1uF | D12: C_0402_1005Metric | E12: C52923 | F12: CL05A105KA5NQNC | G12: Samsung Electro-Mechanics | H12: 1uF 25V X5R 0402 | I12: 1 uF 25 V capacitors for supply decoupling (C12, C14, C17, C18). Main PCB. | J12: =LEN(B12)-LEN(SUBSTITUTE(B12,",",""))+1 -> 4 | K12: 2 | L12: Basic | M12: JLC page | N12: 598000 | O12: OK | P12: p0402 | Q12: =INDEX($C$53:$C$56,MATCH(P12,$B$53:$B$56,0)) -> 10 | R12: =J12*$C$5+Q12 -> 18 | S12: =INDEX($AD12:$AI12,MAX(1,COUNTIF($X12:$AC12,"<="&R12))) -> 0.0085 | T12: =R12*S12 -> 0.153 | U12: =J12*$C$6+Q12 -> 30 | V12: =INDEX($AD12:$AI12,MAX(1,COUNTIF($X12:$AC12,"<="&U12))) -> 0.0085 | W12: =U12*V12 -> 0.255 | X12: 50 | Y12: 500 | Z12: 1500 | AA12: 10000 | AB12: 20000 | AC12: 50000 | AD12: 0.0085 | AE12: 0.0067 | AF12: 0.0059 | AG12: 0.0053 | AH12: 0.005 | AI12: 0.0049 | AJ12: https://www.lcsc.com/product-detail/C52923.html (read 2026-10-14)
A13: 5 | B13: C11,C23 | C13: 10nF | D13: C_0402_1005Metric | E13: C15195 | F13: CL05B103KB5NNNC | G13: Samsung Electro-Mechanics | H13: 10nF 50V X7R 0402 | I13: 10 nF capacitors: C11 (filter in the LED-current loop) and C23 (charge-pump capacitor of the buck U2). Main PCB. | J13: =LEN(B13)-LEN(SUBSTITUTE(B13,",",""))+1 -> 2 | K13: 2 | L13: Basic | M13: JLC page | N13: 0 | O13: LCSC retail shows OUT OF STOCK; JLC lists it as Basic and has its own warehouse - the BOM upload shows the real JLC stock. If flagged, pick another Basic 10 nF 0402 and update flashka_parts.py. | P13: p0402 | Q13: =INDEX($C$53:$C$56,MATCH(P13,$B$53:$B$56,0)) -> 10 | R13: =J13*$C$5+Q13 -> 14 | S13: =INDEX($AD13:$AI13,MAX(1,COUNTIF($X13:$AC13,"<="&R13))) -> 0.005 | T13: =R13*S13 -> 0.07 | U13: =J13*$C$6+Q13 -> 20 | V13: =INDEX($AD13:$AI13,MAX(1,COUNTIF($X13:$AC13,"<="&U13))) -> 0.005 | W13: =U13*V13 -> 0.1 | X13: 100 | Y13: 1000 | Z13: 3000 | AA13: 10000 | AB13: 50000 | AC13: 100000 | AD13: 0.005 | AE13: 0.0038 | AF13: 0.0033 | AG13: 0.0029 | AH13: 0.0028 | AI13: 0.0027 | AJ13: https://www.lcsc.com/product-detail/C15195.html (read 2026-10-14)
A14: 6 | B14: C10,C16,C19,C20,C24 | C14: 100nF | D14: C_0402_1005Metric | E14: C1525 | F14: CL05B104KO5NNNC | G14: Samsung Electro-Mechanics | H14: 100nF 16V X7R 0402 | I14: 100 nF capacitors: next to the chips' supply pins (C10, C16, C19, C20) and the supply filter of the protection IC U6 (C24). Main PCB. | J14: =LEN(B14)-LEN(SUBSTITUTE(B14,",",""))+1 -> 5 | K14: 2 | L14: Basic | M14: JLC page | N14: 0 | O14: LCSC retail shows OUT OF STOCK, but the JLC basic-parts list shows 23,496,493 pcs (read 2026-10-14), so JLC can assemble it. | P14: p0402 | Q14: =INDEX($C$53:$C$56,MATCH(P14,$B$53:$B$56,0)) -> 10 | R14: =J14*$C$5+Q14 -> 20 | S14: =INDEX($AD14:$AI14,MAX(1,COUNTIF($X14:$AC14,"<="&R14))) -> 0.0046 | T14: =R14*S14 -> 0.092 | U14: =J14*$C$6+Q14 -> 35 | V14: =INDEX($AD14:$AI14,MAX(1,COUNTIF($X14:$AC14,"<="&U14))) -> 0.0046 | W14: =U14*V14 -> 0.161 | X14: 100 | Y14: 1000 | Z14: 3000 | AA14: 10000 | AB14: 50000 | AC14: 100000 | AD14: 0.0046 | AE14: 0.0035 | AF14: 0.003 | AG14: 0.0026 | AH14: 0.0025 | AI14: 0.0024 | AJ14: https://www.lcsc.com/product-detail/C1525.html (read 2026-10-14)
A15: 7 | B15: D1 | C15: ESD5Z5.0T1G | D15: D_SOD-523 | E15: C82044 | F15: ESD5Z5.0T1G | G15: onsemi | H15: 5 V unidirectional TVS (VBUS), SOD-523 | I15: D1: protects the board from static / voltage spikes on the USB 5 V line. Main PCB. | J15: =LEN(B15)-LEN(SUBSTITUTE(B15,",",""))+1 -> 1 | K15: 2 | L15: Extended | M15: JLC page | N15: 370780 | O15: OK | P15: semi | Q15: =INDEX($C$53:$C$56,MATCH(P15,$B$53:$B$56,0)) -> 2 | R15: =J15*$C$5+Q15 -> 4 | S15: =INDEX($AD15:$AI15,MAX(1,COUNTIF($X15:$AC15,"<="&R15))) -> 0.0371 | T15: =R15*S15 -> 0.1484 | U15: =J15*$C$6+Q15 -> 7 | V15: =INDEX($AD15:$AI15,MAX(1,COUNTIF($X15:$AC15,"<="&U15))) -> 0.0371 | W15: =U15*V15 -> 0.2597 | X15: 20 | Y15: 200 | Z15: 600 | AA15: 3000 | AB15: 9000 | AC15: 21000 | AD15: 0.0371 | AE15: 0.029 | AF15: 0.0245 | AG15: 0.0204 | AH15: 0.0181 | AI15: 0.0168 | AJ15: https://www.lcsc.com/product-detail/C82044.html (read 2026-10-14)
A16: 8 | B16: J1 | C16: TYPE-C-31-M-12 | D16: USB_C_Receptacle_HRO_TYPE-C-31-M-12 | E16: C165948 | F16: TYPE-C-31-M-12 | G16: Korean Hroparts Elec | H16: USB-C 16P receptacle (USB 2.0 data), SMD + 4 shell legs | I16: J1: USB-C socket (charging and data). 16 signal pads + 4 shell legs = 20 joints. Main PCB. | J16: =LEN(B16)-LEN(SUBSTITUTE(B16,",",""))+1 -> 1 | K16: 20 | L16: Extended | M16: JLC page | N16: 375745 | O16: OK | P16: mod | Q16: =INDEX($C$53:$C$56,MATCH(P16,$B$53:$B$56,0)) -> 1 | R16: =J16*$C$5+Q16 -> 3 | S16: =INDEX($AD16:$AI16,MAX(1,COUNTIF($X16:$AC16,"<="&R16))) -> 0.1729 | T16: =R16*S16 -> 0.5187 | U16: =J16*$C$6+Q16 -> 6 | V16: =INDEX($AD16:$AI16,MAX(1,COUNTIF($X16:$AC16,"<="&U16))) -> 0.1729 | W16: =U16*V16 -> 1.0374 | X16: 5 | Y16: 50 | Z16: 150 | AA16: 1000 | AB16: 2000 | AC16: 5000 | AD16: 0.1729 | AE16: 0.1365 | AF16: 0.1187 | AG16: 0.0963 | AH16: 0.092 | AI16: 0.0894 | AJ16: https://www.lcsc.com/product-detail/C165948.html (read 2026-10-14)
A17: 9 | B17: L1 | C17: 1uH | D17: L_Changjiang_FNR4020S | E17: C602028 | F17: FHD4020S-1R0MT | G17: cjiang | H17: 1 uH 4x4 mm, Isat 11 A, 23 mOhm (cjiang FHD4020S-1R0MT) | I17: L1: 1 uH power inductor of the buck converter U2 (LED driver). Main PCB. | J17: =LEN(B17)-LEN(SUBSTITUTE(B17,",",""))+1 -> 1 | K17: 2 | L17: Extended | M17: JLC page | N17: 8210 | O17: OK | P17: mod | Q17: =INDEX($C$53:$C$56,MATCH(P17,$B$53:$B$56,0)) -> 1 | R17: =J17*$C$5+Q17 -> 3 | S17: =INDEX($AD17:$AI17,MAX(1,COUNTIF($X17:$AC17,"<="&R17))) -> 0.1102 | T17: =R17*S17 -> 0.3306 | U17: =J17*$C$6+Q17 -> 6 | V17: =INDEX($AD17:$AI17,MAX(1,COUNTIF($X17:$AC17,"<="&U17))) -> 0.1102 | W17: =U17*V17 -> 0.6612 | X17: 10 | Y17: 100 | Z17: 300 | AA17: 3000 | AB17: 6000 | AC17: 9000 | AD17: 0.1102 | AE17: 0.086 | AF17: 0.0726 | AG17: 0.0645 | AH17: 0.0575 | AI17: 0.0538 | AJ17: https://www.lcsc.com/product-detail/C602028.html (read 2026-10-14)
A18: 10 | B18: LED3,LED4 | C18: NH-B1010RGBT-HF | D18: LED_RGB_1010_NH-B1010RGBT | E18: C2874113 | F18: NH-B1010RGBT-HF | G18: NATIONSTAR | H18: ring RGB LED 1x1 mm, common anode (pin 1), KB bottom face, shines into the clear main key | I18: LED3, LED4: the two RGB ring LEDs (1 x 1 mm, 4 pads under the package) on the bottom face of the key board; they shine into the clear main key. | J18: =LEN(B18)-LEN(SUBSTITUTE(B18,",",""))+1 -> 2 | K18: 4 | L18: Extended | M18: JLC page | N18: 345020 | O18: OK | P18: semi | Q18: =INDEX($C$53:$C$56,MATCH(P18,$B$53:$B$56,0)) -> 2 | R18: =J18*$C$5+Q18 -> 6 | S18: =INDEX($AD18:$AI18,MAX(1,COUNTIF($X18:$AC18,"<="&R18))) -> 0.0081 | T18: =R18*S18 -> 0.0486 | U18: =J18*$C$6+Q18 -> 12 | V18: =INDEX($AD18:$AI18,MAX(1,COUNTIF($X18:$AC18,"<="&U18))) -> 0.0081 | W18: =U18*V18 -> 0.0972 | X18: 20 | Y18: 200 | Z18: 600 | AA18: 2000 | AB18: 10000 | AC18: 20000 | AD18: 0.0081 | AE18: 0.0072 | AF18: 0.0068 | AG18: 0.0065 | AH18: 0.0063 | AI18: 0.0053 | AJ18: https://www.lcsc.com/product-detail/C2874113.html (read 2026-10-14)
A19: 11 | B19: P1,P2,P3,P4,P5,P6 | C19: P70-1010045R | D19: Pogo_Harwin_P70-1010045R | E19: C22100007 | F19: P70-1010045R | G19: Harwin | H19: SMT pogo pin, gold, no peg, free 5.0 / working 4.0 mm, 1.17 N (Harwin P70-1010045R), KB top face | I19: P1-P6: the six gold spring contacts (pogo pins) on the top face of the key board; they press on the six round pads J6 of the main PCB (SMT, no peg, free height 5.0 mm, working height 4.0 mm, 1.17 N). | J19: =LEN(B19)-LEN(SUBSTITUTE(B19,",",""))+1 -> 6 | K19: 1 | L19: Extended | M19: JLC page | N19: 100 | O19: New in v0.7. LCSC retail stock 100 pcs on 2026-10-21 (enough for 2 or 5 panels). JLCPCB's own stock and library type were not read ('Extended' assumed): if the BOM upload shows no stock, buy the pins into your JLCPCB parts library first (Parts Manager, order from LCSC stock). Other source: Digikey USD 0.696 at 100 pcs, 21 weeks lead time (https://azcus.digikey.com/en/products/detail/harwin-inc/P70-1010045R/6211190). | P19: mod | Q19: =INDEX($C$53:$C$56,MATCH(P19,$B$53:$B$56,0)) -> 1 | R19: =J19*$C$5+Q19 -> 13 | S19: =INDEX($AD19:$AI19,MAX(1,COUNTIF($X19:$AC19,"<="&R19))) -> 1.89 | T19: =R19*S19 -> 24.57 | U19: =J19*$C$6+Q19 -> 31 | V19: =INDEX($AD19:$AI19,MAX(1,COUNTIF($X19:$AC19,"<="&U19))) -> 1.44 | W19: =U19*V19 -> 44.64 | X19: 1 | Y19: 30 | Z19: 100 | AD19: 1.89 | AE19: 1.44 | AF19: 1.26 | AJ19: https://www.lcsc.com/product-detail/C22100007.html (read 2026-10-21)
A20: 12 | B20: Q1 | C20: AO3401A | D20: SOT-23 | E20: C15127 | F20: AO3401A | G20: AOS | H20: P-MOSFET laser load switch | I20: Q1: P-channel MOSFET, the on/off switch of the laser. Main PCB. | J20: =LEN(B20)-LEN(SUBSTITUTE(B20,",",""))+1 -> 1 | K20: 3 | L20: Basic | M20: JLC page | N20: 164910 | O20: OK | P20: semi | Q20: =INDEX($C$53:$C$56,MATCH(P20,$B$53:$B$56,0)) -> 2 | R20: =J20*$C$5+Q20 -> 4 | S20: =INDEX($AD20:$AI20,MAX(1,COUNTIF($X20:$AC20,"<="&R20))) -> 0.1026 | T20: =R20*S20 -> 0.4104 | U20: =J20*$C$6+Q20 -> 7 | V20: =INDEX($AD20:$AI20,MAX(1,COUNTIF($X20:$AC20,"<="&U20))) -> 0.1026 | W20: =U20*V20 -> 0.7182 | X20: 5 | Y20: 50 | Z20: 150 | AA20: 500 | AB20: 3000 | AC20: 6000 | AD20: 0.1026 | AE20: 0.0829 | AF20: 0.0728 | AG20: 0.0644 | AH20: 0.0615 | AI20: 0.0596 | AJ20: https://www.lcsc.com/product-detail/C15127.html (read 2026-10-14)
A21: 13 | B21: Q3 | C21: SE8830A | D21: SOT-23-6 | E21: C238645 | F21: SE8830A | G21: SINO-IC | H21: dual N-MOSFET 20 V common drain, 11/14.5 mOhm at 4.5 V, SOT-23-6 (SINO-IC SE8830A): Q3A discharge (S1 = cell minus), Q3B charge (S2 = board GND) | I21: Q3: dual N-MOSFET (13 / 14.5 mOhm typical / maximum at 4.5 V) in the cell minus, switched by U6, which senses its drop directly (Kelvin tracks); the DW01A trips at about 4.3-4.5 A with hot MOSFETs (5.3-5.6 A at 25 C; 3.0-3.15 A in the worst case). Main PCB, bottom face. | J21: =LEN(B21)-LEN(SUBSTITUTE(B21,",",""))+1 -> 1 | K21: 6 | L21: Extended | M21: JLC page | N21: unknown | O21: ESTIMATE, page not read: the LCSC page of C238645 could not be read on 2026-10-22 (price and stock unknown; library type 'Extended' assumed). No drop-in substitute: an 8205A-type dual MOSFET has about twice the on-resistance, and the DW01A would then cut the light off in turbo (trip at about 2-3 A). If the BOM upload shows no stock, buy it into your JLCPCB parts library from LCSC stock or wait for stock. Before ordering, check the pin order in the data sheet: pins 1-6 must be S1, D, S2, G2, D, G1 (as on the FS8205A; the LCSC data sheet shows it only as a picture). The board is laid out for exactly this order. | P21: semi | Q21: =INDEX($C$53:$C$56,MATCH(P21,$B$53:$B$56,0)) -> 2 | R21: =J21*$C$5+Q21 -> 4 | S21: =INDEX($AD21:$AI21,MAX(1,COUNTIF($X21:$AC21,"<="&R21))) -> 0.1 | T21: =R21*S21 -> 0.4 | U21: =J21*$C$6+Q21 -> 7 | V21: =INDEX($AD21:$AI21,MAX(1,COUNTIF($X21:$AC21,"<="&U21))) -> 0.1 | W21: =U21*V21 -> 0.7 | X21: 10 | Y21: 100 | AD21: 0.1 | AE21: 0.08 | AJ21: ESTIMATE - the LCSC page of C238645 could not be read on 2026-10-22. Priced at about twice the common FS8205A dual MOSFET (C2830320: USD 0.050 from 10 pieces, LCSC, read 2026-10-22).
A22: 14 | B22: Q2,Q4,Q5 | C22: 2N7002W | D22: SOT-323_SC-70 | E22: C5224240 | F22: 2N7002W-7-F-ES | G22: ElecSuper | H22: Q2: N-MOSFET current sink into FB (SOT-323); Q4: N-MOSFET (SOT-323): 3.3 V LASER_ON -> pulls the Q1 gate path low; Q5: VBUS-edge reset (SOT-323): pulls EN low for ~0.1 s when USB is plugged in | I22: Q2, Q4, Q5: small N-channel MOSFET switches (LED current sink, laser gate, reset pulse). Main PCB. | J22: =LEN(B22)-LEN(SUBSTITUTE(B22,",",""))+1 -> 3 | K22: 3 | L22: Extended | M22: JLC page | N22: 17000 | O22: OK | P22: semi | Q22: =INDEX($C$53:$C$56,MATCH(P22,$B$53:$B$56,0)) -> 2 | R22: =J22*$C$5+Q22 -> 8 | S22: =INDEX($AD22:$AI22,MAX(1,COUNTIF($X22:$AC22,"<="&R22))) -> 0.0224 | T22: =R22*S22 -> 0.1792 | U22: =J22*$C$6+Q22 -> 17 | V22: =INDEX($AD22:$AI22,MAX(1,COUNTIF($X22:$AC22,"<="&U22))) -> 0.0224 | W22: =U22*V22 -> 0.3808 | X22: 50 | Y22: 500 | Z22: 3000 | AA22: 6000 | AB22: 24000 | AC22: 51000 | AD22: 0.0224 | AE22: 0.017 | AF22: 0.0141 | AG22: 0.0123 | AH22: 0.0108 | AI22: 0.0099 | AJ22: https://www.lcsc.com/product-detail/C5224240.html (read 2026-10-14)
A23: 15 | B23: R1,R2 | C23: 5.1k | D23: R_0402_1005Metric | E23: C25905 | F23: 0402WGF5101TCE | G23: UNI-ROYAL | H23: 5.1k 1% 0402 resistor | I23: R1, R2: 5.1 k resistors on the USB-C CC pins (tell a charger to supply 5 V). Main PCB. | J23: =LEN(B23)-LEN(SUBSTITUTE(B23,",",""))+1 -> 2 | K23: 2 | L23: Basic | M23: JLC page | N23: 2302500 | O23: OK | P23: p0402 | Q23: =INDEX($C$53:$C$56,MATCH(P23,$B$53:$B$56,0)) -> 10 | R23: =J23*$C$5+Q23 -> 14 | S23: =INDEX($AD23:$AI23,MAX(1,COUNTIF($X23:$AC23,"<="&R23))) -> 0.0024 | T23: =R23*S23 -> 0.0336 | U23: =J23*$C$6+Q23 -> 20 | V23: =INDEX($AD23:$AI23,MAX(1,COUNTIF($X23:$AC23,"<="&U23))) -> 0.0024 | W23: =U23*V23 -> 0.048 | X23: 100 | Y23: 1000 | Z23: 3000 | AA23: 10000 | AB23: 50000 | AD23: 0.0024 | AE23: 0.0019 | AF23: 0.0015 | AG23: 0.0014 | AH23: 0.0012 | AJ23: https://www.lcsc.com/product-detail/C25905.html (read 2026-10-14)
A24: 16 | B24: R3 | C24: 2k | D24: R_0402_1005Metric | E24: C4109 | F24: 0402WGF2001TCE | G24: UNI-ROYAL | H24: 2k 1% 0402 resistor | I24: R3: 2.0 k resistor, sets the battery charge current (about 494 mA, the standard charge of the 14500 cell). Main PCB. | J24: =LEN(B24)-LEN(SUBSTITUTE(B24,",",""))+1 -> 1 | K24: 2 | L24: Basic | M24: JLC page | N24: 5175800 | O24: New for the 14500 cell (R3 was 3.3 k, C25890, about 280 mA). Tiers and stock read on LCSC's product-image page https://www.lcsc.com/product-image/C4109.html (the product page could not be opened); library type Basic as read on 2026-10-14 (the same part was R16 of v0.6). | P24: p0402 | Q24: =INDEX($C$53:$C$56,MATCH(P24,$B$53:$B$56,0)) -> 10 | R24: =J24*$C$5+Q24 -> 12 | S24: =INDEX($AD24:$AI24,MAX(1,COUNTIF($X24:$AC24,"<="&R24))) -> 0.0026 | T24: =R24*S24 -> 0.0312 | U24: =J24*$C$6+Q24 -> 15 | V24: =INDEX($AD24:$AI24,MAX(1,COUNTIF($X24:$AC24,"<="&U24))) -> 0.0026 | W24: =U24*V24 -> 0.039 | X24: 100 | Y24: 1000 | Z24: 3000 | AA24: 10000 | AB24: 50000 | AD24: 0.0026 | AE24: 0.002 | AF24: 0.0016 | AG24: 0.0015 | AH24: 0.0012 | AJ24: https://www.lcsc.com/product-detail/C4109.html (read 2026-10-23)
A25: 17 | B25: R10 | C25: 200k | D25: R_0402_1005Metric | E25: C25764 | F25: 0402WGF2003TCE | G25: UNI-ROYAL | H25: 200k 1% 0402 resistor | I25: R10: 200 k resistor (voltage divider of the buck converter). Main PCB. | J25: =LEN(B25)-LEN(SUBSTITUTE(B25,",",""))+1 -> 1 | K25: 2 | L25: Basic | M25: JLC page | N25: 1520700 | O25: OK | P25: p0402 | Q25: =INDEX($C$53:$C$56,MATCH(P25,$B$53:$B$56,0)) -> 10 | R25: =J25*$C$5+Q25 -> 12 | S25: =INDEX($AD25:$AI25,MAX(1,COUNTIF($X25:$AC25,"<="&R25))) -> 0.0018 | T25: =R25*S25 -> 0.0216 | U25: =J25*$C$6+Q25 -> 15 | V25: =INDEX($AD25:$AI25,MAX(1,COUNTIF($X25:$AC25,"<="&U25))) -> 0.0018 | W25: =U25*V25 -> 0.027 | X25: 100 | Y25: 1000 | Z25: 3000 | AA25: 10000 | AB25: 50000 | AD25: 0.0018 | AE25: 0.0014 | AF25: 0.0011 | AG25: 0.001 | AH25: 0.0009 | AJ25: https://www.lcsc.com/product-detail/C25764.html (read 2026-10-14)
A26: 18 | B26: R12 | C26: 47k | D26: R_0402_1005Metric | E26: C25792 | F26: 0402WGF4702TCE | G26: UNI-ROYAL | H26: 47k 1% 0402 resistor | I26: R12: 47 k resistor. Main PCB. | J26: =LEN(B26)-LEN(SUBSTITUTE(B26,",",""))+1 -> 1 | K26: 2 | L26: Basic | M26: JLC page | N26: 3114700 | O26: OK | P26: p0402 | Q26: =INDEX($C$53:$C$56,MATCH(P26,$B$53:$B$56,0)) -> 10 | R26: =J26*$C$5+Q26 -> 12 | S26: =INDEX($AD26:$AI26,MAX(1,COUNTIF($X26:$AC26,"<="&R26))) -> 0.0026 | T26: =R26*S26 -> 0.0312 | U26: =J26*$C$6+Q26 -> 15 | V26: =INDEX($AD26:$AI26,MAX(1,COUNTIF($X26:$AC26,"<="&U26))) -> 0.0026 | W26: =U26*V26 -> 0.039 | X26: 100 | Y26: 1000 | Z26: 3000 | AA26: 10000 | AB26: 50000 | AD26: 0.0026 | AE26: 0.002 | AF26: 0.0017 | AG26: 0.0015 | AH26: 0.0013 | AJ26: https://www.lcsc.com/product-detail/C25792.html (read 2026-10-14)
A27: 19 | B27: R8,R9,R13,R18,R21,R22 | C27: 10k | D27: R_0402_1005Metric | E27: C25744 | F27: 0402WGF1002TCE | G27: UNI-ROYAL | H27: 10k 1% 0402 resistor | I27: 10 k resistors: pull-ups / pull-downs (R8, R9, R13, R18, R21, R22). Main PCB. | J27: =LEN(B27)-LEN(SUBSTITUTE(B27,",",""))+1 -> 6 | K27: 2 | L27: Basic | M27: JLC page | N27: 2846900 | O27: OK | P27: p0402 | Q27: =INDEX($C$53:$C$56,MATCH(P27,$B$53:$B$56,0)) -> 10 | R27: =J27*$C$5+Q27 -> 22 | S27: =INDEX($AD27:$AI27,MAX(1,COUNTIF($X27:$AC27,"<="&R27))) -> 0.0033 | T27: =R27*S27 -> 0.0726 | U27: =J27*$C$6+Q27 -> 40 | V27: =INDEX($AD27:$AI27,MAX(1,COUNTIF($X27:$AC27,"<="&U27))) -> 0.0033 | W27: =U27*V27 -> 0.132 | X27: 100 | Y27: 1000 | Z27: 3000 | AA27: 10000 | AB27: 50000 | AD27: 0.0033 | AE27: 0.0026 | AF27: 0.0022 | AG27: 0.0021 | AH27: 0.0017 | AJ27: https://www.lcsc.com/product-detail/C25744.html (read 2026-10-14)
A28: 20 | B28: R14,R16,R31 | C28: 2.2k | D28: R_0402_1005Metric | E28: C25879 | F28: 0402WGF2201TCE | G28: UNI-ROYAL | H28: 2.2k 1% 0402 resistor | I28: 2.2 k resistors: R14 (LED-current loop) and R16 (VSET divider: sets the full-scale LED current to 3,552 mA), main PCB; R31 (button ladder, previous key), key board. | J28: =LEN(B28)-LEN(SUBSTITUTE(B28,",",""))+1 -> 3 | K28: 2 | L28: Basic | M28: JLC page | N28: 586000 | O28: OK | P28: p0402 | Q28: =INDEX($C$53:$C$56,MATCH(P28,$B$53:$B$56,0)) -> 10 | R28: =J28*$C$5+Q28 -> 16 | S28: =INDEX($AD28:$AI28,MAX(1,COUNTIF($X28:$AC28,"<="&R28))) -> 0.0018 | T28: =R28*S28 -> 0.0288 | U28: =J28*$C$6+Q28 -> 25 | V28: =INDEX($AD28:$AI28,MAX(1,COUNTIF($X28:$AC28,"<="&U28))) -> 0.0018 | W28: =U28*V28 -> 0.045 | X28: 100 | Y28: 1000 | Z28: 3000 | AA28: 50000 | AD28: 0.0018 | AE28: 0.0013 | AF28: 0.0011 | AG28: 0.0009 | AJ28: https://www.lcsc.com/product-detail/C25879.html (read 2026-10-14)
A29: 21 | B29: R23,R32 | C29: 330Ω | D29: R_0402_1005Metric | E29: C25104 | F29: 0402WGF3300TCE | G29: UNI-ROYAL | H29: 330 1% 0402 resistor | I29: R23, R32: 330 ohm resistors (red leg of the two ring LEDs). Key board. | J29: =LEN(B29)-LEN(SUBSTITUTE(B29,",",""))+1 -> 2 | K29: 2 | L29: Basic | M29: JLC page | N29: unknown | O29: ESTIMATE, page not read: JLCPCB and LCSC pages of C25104 could not be read on 2026-10-18 (not read again in v0.7). Tiers copied from the sibling 5.1 k resistor C25905 (read 2026-10-14); part number inferred from the UNI-ROYAL naming; library type 'Basic' assumed (same series as the other Basic 0402 resistors). Stock unknown. | P29: p0402 | Q29: =INDEX($C$53:$C$56,MATCH(P29,$B$53:$B$56,0)) -> 10 | R29: =J29*$C$5+Q29 -> 14 | S29: =INDEX($AD29:$AI29,MAX(1,COUNTIF($X29:$AC29,"<="&R29))) -> 0.0024 | T29: =R29*S29 -> 0.0336 | U29: =J29*$C$6+Q29 -> 20 | V29: =INDEX($AD29:$AI29,MAX(1,COUNTIF($X29:$AC29,"<="&U29))) -> 0.0024 | W29: =U29*V29 -> 0.048 | X29: 100 | Y29: 1000 | Z29: 3000 | AA29: 10000 | AB29: 50000 | AD29: 0.0024 | AE29: 0.0019 | AF29: 0.0015 | AG29: 0.0014 | AH29: 0.0012 | AJ29: ESTIMATE - LCSC and JLCPCB pages of C25104 could not be read on 2026-10-18. Tiers of the sibling C25905 (LCSC, read 2026-10-14).
A30: 22 | B30: R27,R28 | C30: 1M | D30: R_0402_1005Metric | E30: C26083 | F30: 0402WGF1004TCE | G30: UNI-ROYAL | H30: 1M 1% 0402 resistor | I30: R27, R28: 1 M resistors. Main PCB. | J30: =LEN(B30)-LEN(SUBSTITUTE(B30,",",""))+1 -> 2 | K30: 2 | L30: Basic | M30: JLC page | N30: 541000 | O30: OK | P30: p0402 | Q30: =INDEX($C$53:$C$56,MATCH(P30,$B$53:$B$56,0)) -> 10 | R30: =J30*$C$5+Q30 -> 14 | S30: =INDEX($AD30:$AI30,MAX(1,COUNTIF($X30:$AC30,"<="&R30))) -> 0.0024 | T30: =R30*S30 -> 0.0336 | U30: =J30*$C$6+Q30 -> 20 | V30: =INDEX($AD30:$AI30,MAX(1,COUNTIF($X30:$AC30,"<="&U30))) -> 0.0024 | W30: =U30*V30 -> 0.048 | X30: 100 | Y30: 1000 | Z30: 3000 | AA30: 10000 | AB30: 50000 | AD30: 0.0024 | AE30: 0.0018 | AF30: 0.0016 | AG30: 0.0014 | AH30: 0.0011 | AJ30: https://www.lcsc.com/product-detail/C26083.html (read 2026-10-14)
A31: 23 | B31: R7,R11,R15,R17,R20,R26,R29 | C31: 100k | D31: R_0402_1005Metric | E31: C25741 | F31: 0402WGF1003TCE | G31: UNI-ROYAL | H31: 100k 1% 0402 resistor | I31: 100 k resistors: pull-ups / dividers (7 of them). Main PCB. | J31: =LEN(B31)-LEN(SUBSTITUTE(B31,",",""))+1 -> 7 | K31: 2 | L31: Basic | M31: JLC page | N31: 3791500 | O31: OK | P31: p0402 | Q31: =INDEX($C$53:$C$56,MATCH(P31,$B$53:$B$56,0)) -> 10 | R31: =J31*$C$5+Q31 -> 24 | S31: =INDEX($AD31:$AI31,MAX(1,COUNTIF($X31:$AC31,"<="&R31))) -> 0.0015 | T31: =R31*S31 -> 0.036 | U31: =J31*$C$6+Q31 -> 45 | V31: =INDEX($AD31:$AI31,MAX(1,COUNTIF($X31:$AC31,"<="&U31))) -> 0.0015 | W31: =U31*V31 -> 0.0675 | X31: 100 | Y31: 1000 | Z31: 3000 | AA31: 10000 | AB31: 50000 | AD31: 0.0015 | AE31: 0.0012 | AF31: 0.001 | AG31: 0.0009 | AH31: 0.0008 | AJ31: https://www.lcsc.com/product-detail/C25741.html (read 2026-10-14)
A32: 24 | B32: R24,R25,R33,R34,R35 | C32: 100Ω | D32: R_0402_1005Metric | E32: C25076 | F32: 0402WGF1000TCE | G32: UNI-ROYAL | H32: 100 1% 0402 resistor | I32: 100 ohm resistors: R24, R25, R33, R34 (green and blue leg of each ring LED), key board; R35 (supply filter of the protection IC U6), main PCB. | J32: =LEN(B32)-LEN(SUBSTITUTE(B32,",",""))+1 -> 5 | K32: 2 | L32: Basic | M32: JLC page | N32: 4360400 | O32: OK | P32: p0402 | Q32: =INDEX($C$53:$C$56,MATCH(P32,$B$53:$B$56,0)) -> 10 | R32: =J32*$C$5+Q32 -> 20 | S32: =INDEX($AD32:$AI32,MAX(1,COUNTIF($X32:$AC32,"<="&R32))) -> 0.0013 | T32: =R32*S32 -> 0.026 | U32: =J32*$C$6+Q32 -> 35 | V32: =INDEX($AD32:$AI32,MAX(1,COUNTIF($X32:$AC32,"<="&U32))) -> 0.0013 | W32: =U32*V32 -> 0.0455 | X32: 100 | Y32: 1000 | Z32: 3000 | AA32: 10000 | AD32: 0.0013 | AE32: 0.001 | AF32: 0.0009 | AG32: 0.0008 | AJ32: https://www.lcsc.com/product-detail/C25076.html (read 2026-10-14)
A33: 25 | B33: R19,R30,R36 | C33: 1k | D33: R_0402_1005Metric | E33: C11702 | F33: 0402WGF1001TCE | G33: UNI-ROYAL | H33: 1k 1% 0402 resistor | I33: 1 k resistors: R19 (laser gate) and R36 (current-sense input of the protection IC U6), main PCB; R30 (button ladder, next key), key board. | J33: =LEN(B33)-LEN(SUBSTITUTE(B33,",",""))+1 -> 3 | K33: 2 | L33: Basic | M33: JLC page | N33: 0 | O33: LCSC retail shows OUT OF STOCK; JLC lists it as Basic - check the JLC stock at BOM upload. | P33: p0402 | Q33: =INDEX($C$53:$C$56,MATCH(P33,$B$53:$B$56,0)) -> 10 | R33: =J33*$C$5+Q33 -> 16 | S33: =INDEX($AD33:$AI33,MAX(1,COUNTIF($X33:$AC33,"<="&R33))) -> 0.0031 | T33: =R33*S33 -> 0.0496 | U33: =J33*$C$6+Q33 -> 25 | V33: =INDEX($AD33:$AI33,MAX(1,COUNTIF($X33:$AC33,"<="&U33))) -> 0.0031 | W33: =U33*V33 -> 0.0775 | X33: 100 | Y33: 1000 | Z33: 3000 | AA33: 10000 | AB33: 50000 | AD33: 0.0031 | AE33: 0.0024 | AF33: 0.002 | AG33: 0.0018 | AH33: 0.0016 | AJ33: https://www.lcsc.com/product-detail/C11702.html (read 2026-10-14)
A34: 26 | B34: RS1 | C34: 20mΩ | D34: R_0805_2012Metric | E34: C92740 | F34: MS05W2F200MT5E | G34: UNI-ROYAL | H34: 20 mOhm 1 % 0.5 W 0805 current sense (Kelvin) | I34: RS1: 20 milliohm current-sense resistor, 0.5 W (measures the LED current; 0.18 W at 3 A). Main PCB. | J34: =LEN(B34)-LEN(SUBSTITUTE(B34,",",""))+1 -> 1 | K34: 2 | L34: Extended | M34: JLC page | N34: 4880 | O34: OK | P34: p0603 | Q34: =INDEX($C$53:$C$56,MATCH(P34,$B$53:$B$56,0)) -> 5 | R34: =J34*$C$5+Q34 -> 7 | S34: =INDEX($AD34:$AI34,MAX(1,COUNTIF($X34:$AC34,"<="&R34))) -> 0.0183 | T34: =R34*S34 -> 0.1281 | U34: =J34*$C$6+Q34 -> 10 | V34: =INDEX($AD34:$AI34,MAX(1,COUNTIF($X34:$AC34,"<="&U34))) -> 0.0183 | W34: =U34*V34 -> 0.183 | X34: 20 | Y34: 200 | Z34: 600 | AA34: 2000 | AD34: 0.0183 | AE34: 0.018 | AF34: 0.0177 | AG34: 0.0174 | AJ34: https://www.lcsc.com/product-detail/C92740.html (read 2026-10-14)
A35: 27 | B35: RT1 | C35: 100k B4250 | D35: R_0402_1005Metric | E35: C77130 | F35: NCP15WF104F03RC | G35: muRata | H35: NTC 100 k B25/50 4250 0402 (Murata NCP15WF104F03RC), PCB front edge | I35: RT1: 100 k NTC thermistor = temperature sensor at the front edge of the main PCB. | J35: =LEN(B35)-LEN(SUBSTITUTE(B35,",",""))+1 -> 1 | K35: 2 | L35: Extended | M35: JLC page | N35: 298120 | O35: OK | P35: p0402 | Q35: =INDEX($C$53:$C$56,MATCH(P35,$B$53:$B$56,0)) -> 10 | R35: =J35*$C$5+Q35 -> 12 | S35: =INDEX($AD35:$AI35,MAX(1,COUNTIF($X35:$AC35,"<="&R35))) -> 0.0219 | T35: =R35*S35 -> 0.2628 | U35: =J35*$C$6+Q35 -> 15 | V35: =INDEX($AD35:$AI35,MAX(1,COUNTIF($X35:$AC35,"<="&U35))) -> 0.0219 | W35: =U35*V35 -> 0.3285 | X35: 20 | Y35: 200 | Z35: 600 | AA35: 2000 | AB35: 10000 | AC35: 20000 | AD35: 0.0219 | AE35: 0.0173 | AF35: 0.0147 | AG35: 0.0132 | AH35: 0.0119 | AI35: 0.0112 | AJ35: https://www.lcsc.com/product-detail/C77130.html (read 2026-10-14)
A36: 28 | B36: S2 | C36: MSK12C02 | D36: SW_SPDT_PCM12 | E36: C431540 | F36: MSK12C02 | G36: SHOU HAN | H36: SPDT slide switch, laser interlock (gate path only) | I36: S2: slide switch = the laser safety interlock. Main PCB. | J36: =LEN(B36)-LEN(SUBSTITUTE(B36,",",""))+1 -> 1 | K36: 7 | L36: Extended | M36: JLC page | N36: 170330 | O36: OK | P36: mod | Q36: =INDEX($C$53:$C$56,MATCH(P36,$B$53:$B$56,0)) -> 1 | R36: =J36*$C$5+Q36 -> 3 | S36: =INDEX($AD36:$AI36,MAX(1,COUNTIF($X36:$AC36,"<="&R36))) -> 0.0543 | T36: =R36*S36 -> 0.1629 | U36: =J36*$C$6+Q36 -> 6 | V36: =INDEX($AD36:$AI36,MAX(1,COUNTIF($X36:$AC36,"<="&U36))) -> 0.0543 | W36: =U36*V36 -> 0.3258 | X36: 10 | Y36: 100 | Z36: 300 | AA36: 3000 | AB36: 6000 | AC36: 9000 | AD36: 0.0543 | AE36: 0.0444 | AF36: 0.0394 | AG36: 0.0337 | AH36: 0.0323 | AI36: 0.0312 | AJ36: https://www.lcsc.com/product-detail/C431540.html (read 2026-10-14)
A37: 29 | B37: SW1,SW2,SW3 | C37: SKRKAEE020 | D37: SW_Push_SPST_NO_Alps_SKRK | E37: C115357 | F37: SKRKAEE020 | G37: ALPSALPINE | H37: SW1: main button: Alps top-push tact switch, 1.6 N, KB bottom face (main key); SW2: next button (>): Alps top-push tact switch, KB bottom face; SW3: previous button (<): Alps top-push tact switch, KB bottom face | I37: SW1, SW2, SW3: the three key switches (main, next, previous) on the bottom face of the key board. Alps top-push tact switch 3.9 x 2.9 x 2.0 mm, 1.6 N, 200k cycles. | J37: =LEN(B37)-LEN(SUBSTITUTE(B37,",",""))+1 -> 3 | K37: 2 | L37: Extended | M37: JLC page | N37: unknown | O37: ESTIMATE, page not read: JLCPCB and LCSC pages of C115357 could not be read on 2026-10-18 (not read again in v0.7). Tiers = the sibling Alps SKRPABE010 (C115360) read on LCSC on 2026-10-16 (qty 10 $0.0759, qty 100 $0.0616). Stock unknown. Library type 'Extended' assumed (every Alps tact switch checked on JLCPCB is Extended). | P37: mod | Q37: =INDEX($C$53:$C$56,MATCH(P37,$B$53:$B$56,0)) -> 1 | R37: =J37*$C$5+Q37 -> 7 | S37: =INDEX($AD37:$AI37,MAX(1,COUNTIF($X37:$AC37,"<="&R37))) -> 0.0759 | T37: =R37*S37 -> 0.5313 | U37: =J37*$C$6+Q37 -> 16 | V37: =INDEX($AD37:$AI37,MAX(1,COUNTIF($X37:$AC37,"<="&U37))) -> 0.0759 | W37: =U37*V37 -> 1.2144 | X37: 10 | Y37: 100 | AD37: 0.0759 | AE37: 0.0616 | AJ37: ESTIMATE - LCSC and JLCPCB pages of C115357 could not be read on 2026-10-18. Tiers of the sibling C115360 (LCSC, read 2026-10-16): qty 10 $0.0759, qty 100 $0.0616.
A38: 30 | B38: U1 | C38: TP4057 | D38: SOT-23-6 | E38: C12044 | F38: TP4057-42-SOT26-R | G38: TOP POWER ASIC | H38: TP4057-42-SOT26-R 500 mA Li-ion linear charger (R3 2.0k = ~500 mA) | I38: U1: battery charger chip (500 mA linear Li-ion charger). Main PCB. | J38: =LEN(B38)-LEN(SUBSTITUTE(B38,",",""))+1 -> 1 | K38: 6 | L38: Extended | M38: JLC page | N38: 32025 | O38: OK | P38: semi | Q38: =INDEX($C$53:$C$56,MATCH(P38,$B$53:$B$56,0)) -> 2 | R38: =J38*$C$5+Q38 -> 4 | S38: =INDEX($AD38:$AI38,MAX(1,COUNTIF($X38:$AC38,"<="&R38))) -> 0.1426 | T38: =R38*S38 -> 0.5704 | U38: =J38*$C$6+Q38 -> 7 | V38: =INDEX($AD38:$AI38,MAX(1,COUNTIF($X38:$AC38,"<="&U38))) -> 0.1426 | W38: =U38*V38 -> 0.9982 | X38: 5 | Y38: 50 | Z38: 150 | AA38: 500 | AB38: 3000 | AC38: 6000 | AD38: 0.1426 | AE38: 0.1166 | AF38: 0.1036 | AG38: 0.0938 | AH38: 0.0761 | AI38: 0.0722 | AJ38: https://www.lcsc.com/product-detail/C12044.html (read 2026-10-14)
A39: 31 | B39: U2 | C39: TPS62095RGTR | D39: VQFN-16-1EP_3x3mm_P0.5mm_EP1.68x1.68mm_TV2 | E39: C139643 | F39: TPS62095RGTR | G39: Texas Instruments | H39: 4 A sync buck (TI TPS62095), 100 % duty mode, VFB 0.8 V, 1.4 MHz, VQFN-16 3x3 (RGT) | I39: U2: 4 A synchronous buck converter that drives the LED (100 % duty mode, VQFN-16 3 x 3 mm: 16 pins + exposed pad = 17 joints). Main PCB. | J39: =LEN(B39)-LEN(SUBSTITUTE(B39,",",""))+1 -> 1 | K39: 17 | L39: Extended | M39: JLC page | N39: 2092 | O39: New with the 1000 lm power stage. LCSC stock 2,092 on 2026-10-22; only the price for 1 piece was read (used for every quantity). | P39: semi | Q39: =INDEX($C$53:$C$56,MATCH(P39,$B$53:$B$56,0)) -> 2 | R39: =J39*$C$5+Q39 -> 4 | S39: =INDEX($AD39:$AI39,MAX(1,COUNTIF($X39:$AC39,"<="&R39))) -> 1.35 | T39: =R39*S39 -> 5.4 | U39: =J39*$C$6+Q39 -> 7 | V39: =INDEX($AD39:$AI39,MAX(1,COUNTIF($X39:$AC39,"<="&U39))) -> 1.35 | W39: =U39*V39 -> 9.45 | X39: 1 | AD39: 1.35 | AJ39: https://www.lcsc.com/product-detail/C139643.html (read 2026-10-22)
A40: 32 | B40: U3 | C40: TLV333IDCKR | D40: SOT-353_SC-70-5 | E40: C181502 | F40: TLV333IDCKR | G40: Texas Instruments | H40: zero-drift op-amp SC-70-5 (DCK), powered from LED_EN | I40: U3: precision op-amp in the LED-current control loop. Main PCB. | J40: =LEN(B40)-LEN(SUBSTITUTE(B40,",",""))+1 -> 1 | K40: 5 | L40: Extended | M40: JLC page | N40: 18425 | O40: OK | P40: semi | Q40: =INDEX($C$53:$C$56,MATCH(P40,$B$53:$B$56,0)) -> 2 | R40: =J40*$C$5+Q40 -> 4 | S40: =INDEX($AD40:$AI40,MAX(1,COUNTIF($X40:$AC40,"<="&R40))) -> 0.3543 | T40: =R40*S40 -> 1.4172 | U40: =J40*$C$6+Q40 -> 7 | V40: =INDEX($AD40:$AI40,MAX(1,COUNTIF($X40:$AC40,"<="&U40))) -> 0.3543 | W40: =U40*V40 -> 2.4801 | X40: 5 | Y40: 50 | Z40: 150 | AA40: 500 | AB40: 3000 | AC40: 6000 | AD40: 0.3543 | AE40: 0.2788 | AF40: 0.2465 | AG40: 0.1927 | AH40: 0.1747 | AI40: 0.1639 | AJ40: https://www.lcsc.com/product-detail/C181502.html (read 2026-10-14)
