Workbook

Sheet Summary
A1: FlashKa Keychain v0.6 - what it really costs
A2: Complete cost of building the light from scratch: electronics (JLCPCB), aluminium housing and stainless caps (JLCCNC), resin print kit (JLC3DP), bought parts, consumables, shipping, EU VAT and customs for Lithuania. Scenario A = you build ONE light (JLCPCB still sells 5 bare boards and assembles at least 2), scenario B = you build FIVE (change B to 2 to see two lights). Prices that did not change from v0.5 were read on 2026-10-14; the pages of the new parts could not be read on 2026-10-18, so those prices are ESTIMATES. Blue on amber cells are ESTIMATES because the shop shows its price only after you upload the files (or the page could not be read) - replace them with the real quote.
A3: Colour code: blue = typed-in number, blue on amber = ESTIMATE, black = formula, green = taken from another sheet. USD is the main currency, EUR = USD / rate.
A5: Inputs
A6: Exchange rate (USD per EUR) | B6: 1.1188 | C6: USD per EUR | D6: ECB euro reference rate of 13 Oct 2026. Change it to the rate of your bank/card. Source: https://www.ecb.europa.eu/stats/policy_and_exchange_rates/euro_reference_exchange_rates/html/eurofxref-graph-usd.en.html (read 2026-10-13)
A7: Scenario A: lights you build | B7: 1 | C7: lights | D7: Scenario A: you build one light.
A8: Scenario B: lights you build | B8: 5 | C8: lights | D8: Scenario B: you build five lights (all JLC minimums are used up).
A9: Price check date (v0.6) | B9: 2026-10-18 | C9: v0.6 check. Prices and fees that did not change keep the date they were read, 2026-10-14 (v0.5 check; LCSC and JLC pages). The JLCPCB and LCSC pages of the new parts (C115357, C25104) could not be read on this date: those lines are ESTIMATES. Re-check before ordering.
A11: Total cost
A12: Cost group | B12: A: total (USD) | C12: A: total (EUR) | D12: A: per light (USD) | E12: A: per light (EUR) | F12: B: total (USD) | G12: B: total (EUR) | H12: B: per light (USD) | I12: B: per light (EUR) | J12: Share of B | K12: Basis
A13: Lights built | B13: =$B$7 -> 1 | F13: =$B$8 -> 5
A14: 1. PCB + assembly (JLCPCB) | B14: ='JLCPCB order'!$E$77 -> 174.32774 | C14: =B14/$B$6 -> 155.81671 | D14: =B14/$B$7 -> 174.32774 | E14: =D14/$B$6 -> 155.81671 | F14: ='JLCPCB order'!$G$77 -> 194.68669 | G14: =F14/$B$6 -> 174.01385 | H14: =F14/$B$8 -> 38.937338 | I14: =H14/$B$6 -> 34.802769 | J14: =F14/F30 -> 0.16291952 | K14: Fees: JLCPCB price page, read 2026-10-14 (v0.5 check, not refreshed). Parts: LCSC prices read 2026-10-14; the two new lines are ESTIMATES (pages not readable on 2026-10-18). Bare PCB: ESTIMATE.
A15: of which bare PCBs (4 layers, 0.8 mm, ENIG) | B15: ='JLCPCB order'!$E$48 -> 25 | C15: =B15/$B$6 -> 22.34537 | D15: =B15/$B$7 -> 25 | E15: =D15/$B$6 -> 22.34537 | F15: ='JLCPCB order'!$G$48 -> 25 | G15: =F15/$B$6 -> 22.34537 | H15: =F15/$B$8 -> 5 | I15: =H15/$B$6 -> 4.469074 | K15: ESTIMATE - the price appears only after the Gerber upload.
A16: of which assembly fees (set-up, stencil, joints, feeder, X-ray, ...) | B16: ='JLCPCB order'!$E$69 -> 132.01264 | C16: =B16/$B$6 -> 117.99485 | D16: =B16/$B$7 -> 132.01264 | E16: =D16/$B$6 -> 117.99485 | F16: ='JLCPCB order'!$G$69 -> 136.96659 | G16: =F16/$B$6 -> 122.42277 | H16: =F16/$B$8 -> 27.393318 | I16: =H16/$B$6 -> 24.484553 | K16: JLCPCB fee page, sheet 'JLCPCB order'.
A17: of which components (34 lines, 68 parts per board, incl. spares for placement loss) | B17: ='Main PCB BOM'!$T$43 -> 17.3151 | C17: =B17/$B$6 -> 15.476493 | D17: =B17/$B$7 -> 17.3151 | E17: =D17/$B$6 -> 15.476493 | F17: ='Main PCB BOM'!$W$43 -> 32.7201 | G17: =F17/$B$6 -> 29.24571 | H17: =F17/$B$8 -> 6.54402 | I17: =H17/$B$6 -> 5.8491419 | K17: LCSC price tiers, sheet 'Main PCB BOM'.
A18: 2. Housing (aluminium tray + lid, stainless caps, resin print kit) | B18: =Housing!$E$118 -> 122.55751 | C18: =B18/$B$6 -> 109.54372 | D18: =B18/$B$7 -> 122.55751 | E18: =D18/$B$6 -> 109.54372 | F18: =Housing!$G$118 -> 382.38755 | G18: =F18/$B$6 -> 341.78365 | H18: =F18/$B$8 -> 76.477509 | I18: =H18/$B$6 -> 68.35673 | J18: =F18/F30 -> 0.31999308 | K18: ESTIMATE - replace by the JLCCNC / JLC3DP instant quotes.
A19: of which aluminium tray + lid (JLCCNC, bead blast + black anodize, laser marking) | B19: =Housing!$B$88 -> 93.357509 | C19: =B19/$B$6 -> 83.444324 | D19: =B19/$B$7 -> 93.357509 | E19: =D19/$B$6 -> 83.444324 | F19: =Housing!$C$88 -> 302.78755 | G19: =F19/$B$6 -> 270.63599 | H19: =F19/$B$8 -> 60.557509 | I19: =H19/$B$6 -> 54.127198 | K19: ESTIMATE from volume, box, finish and marking, sheet 'Housing'.
A20: of which stainless caps (JLCCNC, SUS304: main x1 + slide x2 per light, +1 spare of each) | B20: =Housing!$C$100 -> 28 | C20: =B20/$B$6 -> 25.026814 | D20: =B20/$B$7 -> 28 | E20: =D20/$B$6 -> 25.026814 | F20: =Housing!$E$100 -> 76 | G20: =F20/$B$6 -> 67.929925 | H20: =F20/$B$8 -> 15.2 | I20: =H20/$B$6 -> 13.585985 | K20: ESTIMATE - JLCCNC publishes no per-part price. Fallback: the resin caps in the print kit (0 extra); switch in sheet 'Housing', section 7.
A21: of which resin print kit (JLC3DP, one kit per light + one spare) | B21: =Housing!$E$117 -> 1.2 | C21: =B21/$B$6 -> 1.0725778 | D21: =B21/$B$7 -> 1.2 | E21: =D21/$B$6 -> 1.0725778 | F21: =Housing!$G$117 -> 3.6 | G21: =F21/$B$6 -> 3.2177333 | H21: =F21/$B$8 -> 0.72 | I21: =H21/$B$6 -> 0.64354666 | K21: ESTIMATE, sheet 'Housing'.
A22: 3. Bought parts (cells, LED board, laser, window, screws, split ring) | B22: ='Bought parts'!$L$21 -> 56.75 | C22: =B22/$B$6 -> 50.72399 | D22: =B22/$B$7 -> 56.75 | E22: =D22/$B$6 -> 50.72399 | F22: ='Bought parts'!$N$21 -> 211.3 | G22: =F22/$B$6 -> 188.86307 | H22: =F22/$B$8 -> 42.26 | I22: =H22/$B$6 -> 37.772614 | J22: =F22/F30 -> 0.17682202 | K22: Typical AliExpress prices (ESTIMATES), sheet 'Bought parts'.
A23: 4. Consumables (wire, thermal tape, Kapton, foam tape, silicone pads and adhesive, epoxy) | B23: ='Bought parts'!$L$22 -> 27.79 | C23: =B23/$B$6 -> 24.839113 | D23: =B23/$B$7 -> 27.79 | E23: =D23/$B$6 -> 24.839113 | F23: ='Bought parts'!$N$22 -> 27.79 | G23: =F23/$B$6 -> 24.839113 | H23: =F23/$B$8 -> 5.558 | I23: =H23/$B$6 -> 4.9678227 | J23: =F23/F30 -> 0.023255484 | K23: Typical prices (ESTIMATES), sheet 'Bought parts'.
A24: 5. Shipping, VAT, customs duty, carrier and bank fees | B24: ='Hidden costs'!$J$39 -> 238.78269 | C24: =B24/$B$6 -> 213.4275 | D24: =B24/$B$7 -> 238.78269 | E24: =D24/$B$6 -> 213.4275 | F24: ='Hidden costs'!$J$49 -> 378.82269 | G24: =F24/$B$6 -> 338.59733 | H24: =F24/$B$8 -> 75.764539 | I24: =H24/$B$6 -> 67.719466 | J24: =F24/F30 -> 0.31700991 | K24: Computed from EU rules and shipping ESTIMATES, sheet 'Hidden costs'.
A25: of which shipping (3 JLC parcels + AliExpress parcels) | B25: ='Hidden costs'!$F$37 -> 81 | C25: =B25/$B$6 -> 72.398999 | D25: =B25/$B$7 -> 81 | E25: =D25/$B$6 -> 72.398999 | F25: ='Hidden costs'!$F$47 -> 84 | G25: =F25/$B$6 -> 75.080443 | H25: =F25/$B$8 -> 16.8 | I25: =H25/$B$6 -> 15.016089 | K25: Shipping per parcel are ESTIMATES (JLC shows them in the cart).
A26: of which VAT 21 % | B26: ='Hidden costs'!$H$37 -> 97.109302 | C26: =B26/$B$6 -> 86.797731 | D26: =B26/$B$7 -> 97.109302 | E26: =D26/$B$6 -> 86.797731 | F26: ='Hidden costs'!$H$47 -> 194.12221 | G26: =F26/$B$6 -> 173.50931 | H26: =F26/$B$8 -> 38.824443 | I26: =H26/$B$6 -> 34.701861 | K26: Lithuania 21 %, collected by JLC at checkout up to EUR 150 per parcel.
A27: of which customs duty and carrier fees | B27: ='Hidden costs'!$G$37+'Hidden costs'!$I$37 -> 53.7024 | C27: =B27/$B$6 -> 48 | D27: =B27/$B$7 -> 53.7024 | E27: =D27/$B$6 -> 48 | F27: ='Hidden costs'!$G$47+'Hidden costs'!$I$47 -> 87.998853 | G27: =F27/$B$6 -> 78.654677 | H27: =F27/$B$8 -> 17.599771 | I27: =H27/$B$6 -> 15.730935 | K27: Flat EUR 3 per customs line up to EUR 150 per parcel; formal clearance + carrier fee above.
A28: of which card / currency conversion fee | B28: ='Hidden costs'!$J$38 -> 6.9709852 | C28: =B28/$B$6 -> 6.2307698 | D28: =B28/$B$7 -> 6.9709852 | E28: =D28/$B$6 -> 6.2307698 | F28: ='Hidden costs'!$J$48 -> 12.701628 | G28: =F28/$B$6 -> 11.352903 | H28: =F28/$B$8 -> 2.5403256 | I28: =H28/$B$6 -> 2.2705806 | K28: ESTIMATE 1.5 % on the USD payments to JLC.
A29: JLCPCB order vs the EUR 150 IOSS line (EUR left; negative = above, formal customs) | B29: ='JLCPCB order'!$E$79 -> -5.8167113 | F29: ='JLCPCB order'!$G$79 -> -24.013847 | G29: Above the line the JLCPCB parcel pays a carrier fee of about EUR 15 (sheet 'Hidden costs', section 6).
A30: TOTAL for the lights (1 + 2 + 3 + 4 + 5) | B30: =B14+B18+B22+B23+B24 -> 620.20793 | C30: =B30/$B$6 -> 554.35103 | D30: =B30/$B$7 -> 620.20793 | E30: =D30/$B$6 -> 554.35103 | F30: =F14+F18+F22+F23+F24 -> 1194.9869 | G30: =F30/$B$6 -> 1068.097 | H30: =F30/$B$8 -> 238.99739 | I30: =H30/$B$6 -> 213.6194 | K30: Per-light columns divide by the number of lights built.
A31: Extra cost of each additional light (scenario B vs A) | B31: =IF($B$8=$B$7,0,(F30-B30)/($B$8-$B$7)) -> 143.69475 | C31: =B31/$B$6 -> 128.43649 | D31: Set-up fees, stencil, feeder loading, the anodizing lot fee, the marking set-up and most shipping are paid once, so the 2nd to 5th light is much cheaper than the first.
A33: What changed from v0.5 (same scenarios and exchange rate; USD)
A34: The v0.5 values are typed in from the v0.5 cost workbook (sheet 'Summary', price check 2026-10-14; the v0.5 package keeps that workbook). Board: 34 BOM lines, 68 placements, 232 solder joints (v0.5: 33, 60, 217) - three push buttons instead of one, a second ring LED, five more resistors, no S1. Housing: new stainless caps and laser marking, a 5.2 mm lid with hold-down bosses, a print kit of seven parts instead of four.
A35: Cost group | B35: v0.5: A | C35: v0.6: A | D35: Change A | E35: v0.5: B | F35: v0.6: B | G35: Change B | H35: What changed
A36: 1. PCB + assembly (JLCPCB) | B36: 169.30974 | C36: =B14 -> 174.32774 | D36: =C36-B36 -> 5.018 | E36: 196.67159 | F36: =F14 -> 194.68669 | G36: =F36-E36 -> -1.9849 | H36: More parts per board (SW1-SW3, LED4, R30-R34; S1 gone): more joints and components, one more unique BOM line (feeder fee) and one more X-ray part per board; the two new price lines are ESTIMATES. With five lights the X-ray price per part falls to the next tier (15 inspected parts instead of 10), so scenario B is slightly cheaper than in v0.5.
A37: 2. Housing | B37: 65.959563 | C37: =B18 -> 122.55751 | D37: =C37-B37 -> 56.597946 | E37: 225.39781 | F37: =F18 -> 382.38755 | G37: =F37-E37 -> 156.98973 | H37: Stainless caps (ESTIMATE) and laser marking (ESTIMATE) are new; the lid is a 5.2 mm part with bosses (bigger block); more set-ups and a higher complexity factor (sheet 'Housing', sections 4 and 5); the print kit has seven parts instead of four, still at the minimum price.
A38: 3. Bought parts | B38: 56.75 | C38: =B22 -> 56.75 | D38: =C38-B38 -> 0 | E38: 211.3 | F38: =F22 -> 211.3 | G38: =F38-E38 -> 0 | H38: Unchanged: cells, LED board, laser, window, screws, ring.
A39: 4. Consumables | B39: 18.29 | C39: =B23 -> 27.79 | D39: =C39-B39 -> 9.5 | E39: 18.29 | F39: =F23 -> 27.79 | G39: =F39-E39 -> 9.5 | H39: New: two silicone hold-down pad sheets and silicone adhesive (ESTIMATES).
A40: 5. Shipping, VAT, customs, fees | B40: 219.32326 | C40: =B24 -> 238.78269 | D40: =C40-B40 -> 19.459424 | E40: 329.89492 | F40: =F24 -> 378.82269 | G40: =F40-E40 -> 48.927769 | H40: Follows from the larger orders: mostly VAT on the dearer housing and JLCPCB order, a second customs line for the stainless caps and a bigger card fee; shipping is unchanged (same parcels). Check the EUR 150 line of the JLCPCB order.
A41: TOTAL for the lights | B41: 529.63256 | C41: =B30 -> 620.20793 | D41: =C41-B41 -> 90.575371 | E41: 981.55433 | F41: =F30 -> 1194.9869 | G41: =F41-E41 -> 213.4326 | H41: Sum of the lines above.
A42: TOTAL per light (A: 1 light, B: 5 lights) | B42: 529.63256 | C42: =D30 -> 620.20793 | D42: =C42-B42 -> 90.575371 | E42: 196.31087 | F42: =H30 -> 238.99739 | G42: =F42-E42 -> 42.68652 | H42: Per-light price in USD; the EUR values are in the table above.
A44: Not in the per-light cost
...

Sheet JLCPCB order
A1: JLCPCB order - bare PCB + Standard PCBA (parts on both sides)
A2: What you order at jlcpcb.com in ONE order: 5 bare 4-layer boards and the assembly (soldering of all SMD parts) of 2 or 5 of them. Column E = scenario A (you build 1 light), column G = scenario B (you build 5 lights). Every fee is a blue input with the date it was read and its URL: the fee page says 'Last updated on Sep 09, 2026' and was read on 2026-10-14 (v0.5 price check, not repeated in v0.6; only the X-ray count changed). Prices change - re-check before you pay.
A3: Colour code: blue = typed-in number, blue on amber = ESTIMATE (no public price), black = formula, green = taken from another sheet.
A5: 1. What to select in the JLCPCB cart (https://cart.jlcpcb.com/quote)
A6: Setting | B6: Value | E6: Why / what to watch
A7: Base material / layers | B7: FR-4, 4 layers | E7: The board is designed as a 4-layer stack-up. Do not change the layer count.
A8: Dimensions | B8: 24.0 x 16.5 mm (JLC reads it from the Gerber) | E8: Outline from housing_interface.json pcb_outline, see section 2.
A9: PCB quantity | B9: 5 | E9: JLCPCB minimum. Four spare boards cost almost nothing and cover first-article problems.
A10: Different designs | B10: 1
A11: PCB thickness | B11: 0.8 mm | E11: The housing is built around a 0.8 mm board (pcb_t 0.8).
A12: Surface finish | B12: ENIG (immersion gold) | E12: Flat pads for the fine-pitch module and LED; costs extra, included in the bare-PCB estimate.
A13: Solder mask / silkscreen / copper | B13: Defaults (green mask, white silkscreen, 1 oz outer, 0.5 oz inner) | E13: Default options carry no surcharge.
A14: Order number on the board | B14: Default (JLC prints a code in a free area) | E14: Removing the code costs extra.
A15: PCB Assembly | B15: ON - Standard PCBA, assemble BOTH sides | E15: Economic PCBA cannot do two-sided boards; set-up and stencil are charged per side.
A16: Assembly quantity | B16: 2 (for one light) or 5 | E16: JLCPCB assembles from 2 boards. The extra board is your spare.
A17: Upload | B17: order_files/1_JLCPCB/FlashKa_main_gerbers.zip, then order_files/1_JLCPCB/BOM_JLCPCB.csv and order_files/1_JLCPCB/CPL_JLCPCB.csv | E17: The three files of order_files/1_JLCPCB/ (written by tools/kicad/build_all.py, copied there by the packaging step). Check that all 34 BOM lines are matched (no red rows) and look at the placement preview.
A18: Confirm parts placement | B18: Yes (recommended for the first order) | E18: JLC sends you a photo of the placed parts for your OK; the rotation of U4, U1, U2, U3, U5, Q1, Q2, Q4, Q5, J1, SW1-SW3, LED3 and LED4 is the classic problem. For the new SW1-SW3 (SKRKAEE020) and LED3/LED4 (NH-B1010RGBT) the rotation and pin 1 in the JLC library are NOT verified: look at the placement preview.
A19: Shipping | B19: Your choice (see sheet 'Hidden costs') | E19: Choose DDP / 'taxes paid' so the VAT is collected at checkout and nothing is asked at your door.
A21: 2. Board outline (read from housing_interface.json -> pcb_outline, mm)
A22: Vertex | B22: x (mm) | C22: y (mm) | D22: next x | E22: next y | F22: x*next y - next x*y
A23: vertex 1 | B23: 10.1 | C23: -8.25 | D23: =B24 -> 32.8 | E23: =C24 -> -8.25 | F23: =B23*E23-D23*C23 -> 187.275
A24: vertex 2 | B24: 32.8 | C24: -8.25 | D24: =B25 -> 32.8 | E24: =C25 -> 8.25 | F24: =B24*E24-D24*C24 -> 541.2
A25: vertex 3 | B25: 32.8 | C25: 8.25 | D25: =B26 -> 10.1 | E25: =C26 -> 8.25 | F25: =B25*E25-D25*C25 -> 187.275
A26: vertex 4 | B26: 10.1 | C26: 8.25 | D26: =B27 -> 8.8 | E26: =C27 -> 6.95 | F26: =B26*E26-D26*C26 -> -2.405
A27: vertex 5 | B27: 8.8 | C27: 6.95 | D27: =B28 -> 8.8 | E27: =C28 -> -6.95 | F27: =B27*E27-D27*C27 -> -122.32
A28: vertex 6 | B28: 8.8 | C28: -6.95 | D28: =B23 -> 10.1 | E28: =C23 -> -8.25 | F28: =B28*E28-D28*C28 -> -2.405
A29: Board width (mm) | B29: =MAX(B23:B28)-MIN(B23:B28) -> 24
A30: Board height (mm) | B30: =MAX(C23:C28)-MIN(C23:C28) -> 16.5
A31: Board area (cm2, shoelace formula) | B31: =ABS(SUM(F23:F28))/2/100 -> 3.9431 | C31: Two corners are chamfered 1.3 mm, so the area is a little smaller than width x height. JLCPCB measures the Gerber itself; the area only feeds the tiny packing fee.
A33: 3. Quantities (JLCPCB minimums: 5 bare boards, assembly from 2 boards)
A34: Minimum boards JLCPCB assembles | B34: 2 | C34: boards | D34: JLCPCB assembles from 2 boards; one light therefore still pays for 2 assembled boards (1 spare). Source: https://jlcpcb.com/pcb-assembly (read 2026-10-14)
A35: Minimum bare boards per design | B35: 5 | C35: boards | D35: JLCPCB sells at least 5 bare boards per design. Source: https://cart.jlcpcb.com/quote (read 2026-10-14)
A36: Assembled sides (double-sided) | B36: 2 | C36: sides | D36: Parts are on both sides of the board = double-sided Standard PCBA (Economic PCBA is single-sided only).
A37: X-ray inspected parts per board (optional) | B37: 3 | C37: parts per board | D37: Fee page: 'X-ray inspection is required for components such as BGA, QFN and other leadless packages', charged per component. The COUNT is a v0.6 assumption (the fee page itself was not re-read in v0.6): v0.6 budgets the three parts of this board with hidden joints: U4 (ESP32 module, pads under it), LED3 and LED4 (pads under the package) = 3 per board (v0.5: 2, there was one ring LED). Set 0 if your cart does not ask for it. Source: https://jlcpcb.com/help/article/pcb-assembly-price (read 2026-10-14)
E38: Scenario A | G38: Scenario B
A39: Lights you build | E39: =Summary!$B$7 -> 1 | G39: =Summary!$B$8 -> 5
A40: Boards assembled by JLCPCB = MAX(lights, minimum) | E40: =MAX(E39,$B$34) -> 2 | G40: =MAX(G39,$B$34) -> 5
A41: Bare PCBs ordered (sold in steps of 5) | E41: =CEILING(MAX($B$35,E40),5) -> 5 | G41: =CEILING(MAX($B$35,G40),5) -> 5
A43: 4. Bare PCB fabrication (4 layers, 0.8 mm, ENIG, 24.0 x 16.5 mm) - the price is shown by JLCPCB only AFTER the Gerber upload
A44: Bare PCBs, price for 5 boards (ESTIMATE) | B44: 25 | C44: USD for 5 boards | D44: ESTIMATE. JLCPCB shows the price only after the Gerber upload. Anchors: 100 x 100 mm 4-layer x 5 is about $32.90 (pcbsync, Jul 2026); ENIG adds roughly $12-20 on small runs; 0.8 mm is a normal thickness; 24 x 16.5 mm is far smaller than 100 x 100 mm. Source: https://cart.jlcpcb.com/quote (read 2026-10-14)
...

Sheet Main PCB BOM
A1: Main PCB bill of materials - what JLCPCB assembles on the board
A2: One line per component type (grouped by LCSC number), generated from tools/kicad/flashka_parts.py with the same grouping and ordering as tools/kicad/build_all.py, which writes the BOM you upload as order_files/1_JLCPCB/BOM_JLCPCB.csv: 34 lines, 68 placements, 232 solder joints per board. Wire pads (J2 cell, J3 LED, J5 laser) have no LCSC number: they are NOT assembled, you solder the wires by hand. The LED board, the cells and the laser are bought parts (sheet 'Bought parts'). New in v0.6: SW1-SW3 (Alps SKRKAEE020, three push buttons on the bottom side), LED4 (second ring LED), R30-R34 (button ladder and LED resistors); S1 is gone.
A3: Unit price = the LCSC price tier that matches the quantity JLCPCB has to buy = (quantity per board x boards assembled) + extra pieces for placement loss (columns P-Q). Prices were read from the LCSC product pages on 2026-10-14 (v0.5 price check; the lines that did not change keep that date) (columns X-AI hold the tier tables, typed in from the page). The two NEW lines whose pages could not be read on 2026-10-18 (C115357, C25104) are blue on amber = ESTIMATE: tiers copied from the sibling parts named in the 'Price source' column. JLC buys from LCSC/its own warehouse; the real component price shows in the JLC cart after the BOM upload.
A4: Basic / Extended = JLCPCB library type read on jlcpcb.com/partdetail/<LCSC number> on 2026-10-14 (assumed, amber, for the two new lines: Extended for C115357, Basic for C25104 - check them in the JLC BOM upload). In 2026 Standard PCBA every unique part costs the same feeder fee, Basic or Extended (see sheet 'JLCPCB order'); the 'Preferred' tag (only relevant for the single-sided Economic PCBA) was not shown on any of these pages. 'LCSC stock' is LCSC's retail stock, NOT JLC's warehouse; JLC flags real shortages when you upload the BOM.
B5: Boards assembled, scenario A | C5: ='JLCPCB order'!$E$40 -> 2
B6: Boards assembled, scenario B | C6: ='JLCPCB order'!$G$40 -> 5
A8: # | B8: Designators | C8: Value | D8: Footprint | E8: LCSC # | F8: Manufacturer part no. | G8: Manufacturer | H8: Description (flashka_parts.py) | I8: What it does | J8: Qty / board | K8: Solder joints / part | L8: JLC part type | M8: JLC part page | N8: LCSC stock (retail) | O8: Stock note | P8: Loss class | Q8: Extra pcs | R8: Buy qty A | S8: Unit USD A | T8: Line USD A | U8: Buy qty B | V8: Unit USD B | W8: Line USD B | X8: Tier 1 from qty | Y8: Tier 2 from qty | Z8: Tier 3 from qty | AA8: Tier 4 from qty | AB8: Tier 5 from qty | AC8: Tier 6 from qty | AD8: Tier 1 USD | AE8: Tier 2 USD | AF8: Tier 3 USD | AG8: Tier 4 USD | AH8: Tier 5 USD | AI8: Tier 6 USD | AJ8: Price source
A9: 1 | B9: C1 | C9: 10uF | D9: C_0805_2012Metric | E9: C15850 | F9: CL21A106KAYNNNE | G9: Samsung Electro-Mechanics | H9: 10uF 25V X5R 0805 | I9: Smoothing capacitor on the USB 5 V input (25 V rating needed). | J9: =LEN(B9)-LEN(SUBSTITUTE(B9,",",""))+1 -> 1 | K9: 2 | L9: Basic | M9: JLC page | N9: 20 | O9: LOW: only 20 pcs at LCSC retail; JLC's own stock is separate - the BOM upload flags a shortage. Any 10 uF 25 V X5R 0805 Basic part is a substitute. | P9: p0603 | Q9: =INDEX($C$52:$C$55,MATCH(P9,$B$52:$B$55,0)) -> 5 | R9: =J9*$C$5+Q9 -> 7 | S9: =INDEX($AD9:$AI9,MAX(1,COUNTIF($X9:$AC9,"<="&R9))) -> 0.0695 | T9: =R9*S9 -> 0.4865 | U9: =J9*$C$6+Q9 -> 10 | V9: =INDEX($AD9:$AI9,MAX(1,COUNTIF($X9:$AC9,"<="&U9))) -> 0.0695 | W9: =U9*V9 -> 0.695 | X9: 20 | Y9: 200 | Z9: 600 | AA9: 2000 | AB9: 10000 | AC9: 20000 | AD9: 0.0695 | AE9: 0.0513 | AF9: 0.0419 | AG9: 0.0342 | AH9: 0.0315 | AI9: 0.0297 | AJ9: https://www.lcsc.com/product-detail/C15850.html (read 2026-10-14)
A10: 2 | B10: C2,C13,C15 | C10: 10uF | D10: C_0603_1608Metric | E10: C19702 | F10: CL10A106KP8NNNC | G10: Samsung Electro-Mechanics | H10: 10uF 10V X5R 0603 | I10: 10 uF capacitors that smooth the supply next to the chips (C2, C13, C15). | J10: =LEN(B10)-LEN(SUBSTITUTE(B10,",",""))+1 -> 3 | K10: 2 | L10: Basic | M10: JLC page | N10: 181020 | O10: OK | P10: p0603 | Q10: =INDEX($C$52:$C$55,MATCH(P10,$B$52:$B$55,0)) -> 5 | R10: =J10*$C$5+Q10 -> 11 | S10: =INDEX($AD10:$AI10,MAX(1,COUNTIF($X10:$AC10,"<="&R10))) -> 0.0311 | T10: =R10*S10 -> 0.3421 | U10: =J10*$C$6+Q10 -> 20 | V10: =INDEX($AD10:$AI10,MAX(1,COUNTIF($X10:$AC10,"<="&U10))) -> 0.0311 | W10: =U10*V10 -> 0.622 | X10: 20 | Y10: 200 | Z10: 600 | AA10: 4000 | AB10: 8000 | AC10: 20000 | AD10: 0.0311 | AE10: 0.023 | AF10: 0.0195 | AG10: 0.0168 | AH10: 0.0157 | AI10: 0.015 | AJ10: https://www.lcsc.com/product-detail/C19702.html (read 2026-10-14)
A11: 3 | B11: C5,C8 | C11: 22uF | D11: C_0603_1608Metric | E11: C59461 | F11: CL10A226MQ8NRNC | G11: Samsung Electro-Mechanics | H11: 22uF 6.3V X5R 0603 | I11: 22 uF capacitors for the buck converter / power rails (C5, C8). | J11: =LEN(B11)-LEN(SUBSTITUTE(B11,",",""))+1 -> 2 | K11: 2 | L11: Basic | M11: JLC page | N11: 4416440 | O11: OK | P11: p0603 | Q11: =INDEX($C$52:$C$55,MATCH(P11,$B$52:$B$55,0)) -> 5 | R11: =J11*$C$5+Q11 -> 9 | S11: =INDEX($AD11:$AI11,MAX(1,COUNTIF($X11:$AC11,"<="&R11))) -> 0.0315 | T11: =R11*S11 -> 0.2835 | U11: =J11*$C$6+Q11 -> 15 | V11: =INDEX($AD11:$AI11,MAX(1,COUNTIF($X11:$AC11,"<="&U11))) -> 0.0315 | W11: =U11*V11 -> 0.4725 | X11: 20 | Y11: 200 | Z11: 600 | AA11: 4000 | AB11: 8000 | AC11: 20000 | AD11: 0.0315 | AE11: 0.0236 | AF11: 0.0201 | AG11: 0.0174 | AH11: 0.0164 | AI11: 0.0157 | AJ11: https://www.lcsc.com/product-detail/C59461.html (read 2026-10-14)
A12: 4 | B12: C9 | C12: 22pF | D12: C_0402_1005Metric | E12: C1555 | F12: 0402CG220J500NT | G12: FH | H12: 22pF 50V C0G 0402 | I12: 22 pF feed-forward capacitor in the LED-driver loop (C9). | J12: =LEN(B12)-LEN(SUBSTITUTE(B12,",",""))+1 -> 1 | K12: 2 | L12: Basic | M12: JLC page | N12: 798400 | O12: OK | P12: p0402 | Q12: =INDEX($C$52:$C$55,MATCH(P12,$B$52:$B$55,0)) -> 10 | R12: =J12*$C$5+Q12 -> 12 | S12: =INDEX($AD12:$AI12,MAX(1,COUNTIF($X12:$AC12,"<="&R12))) -> 0.0027 | T12: =R12*S12 -> 0.0324 | U12: =J12*$C$6+Q12 -> 15 | V12: =INDEX($AD12:$AI12,MAX(1,COUNTIF($X12:$AC12,"<="&U12))) -> 0.0027 | W12: =U12*V12 -> 0.0405 | X12: 100 | Y12: 1000 | Z12: 3000 | AA12: 10000 | AB12: 50000 | AD12: 0.0027 | AE12: 0.002 | AF12: 0.0017 | AG12: 0.0014 | AH12: 0.0012 | AJ12: https://www.lcsc.com/product-detail/C1555.html (read 2026-10-14)
A13: 5 | B13: C11 | C13: 10nF | D13: C_0402_1005Metric | E13: C15195 | F13: CL05B103KB5NNNC | G13: Samsung Electro-Mechanics | H13: 10nF 50V X7R 0402 | I13: 10 nF capacitor (C11, filter in the LED-current loop). | J13: =LEN(B13)-LEN(SUBSTITUTE(B13,",",""))+1 -> 1 | K13: 2 | L13: Basic | M13: JLC page | N13: 0 | O13: LCSC retail shows OUT OF STOCK; JLC lists it as Basic and has its own warehouse - the BOM upload shows the real JLC stock. If flagged, pick another Basic 10 nF 0402 and update flashka_parts.py. | P13: p0402 | Q13: =INDEX($C$52:$C$55,MATCH(P13,$B$52:$B$55,0)) -> 10 | R13: =J13*$C$5+Q13 -> 12 | S13: =INDEX($AD13:$AI13,MAX(1,COUNTIF($X13:$AC13,"<="&R13))) -> 0.005 | T13: =R13*S13 -> 0.06 | U13: =J13*$C$6+Q13 -> 15 | V13: =INDEX($AD13:$AI13,MAX(1,COUNTIF($X13:$AC13,"<="&U13))) -> 0.005 | W13: =U13*V13 -> 0.075 | X13: 100 | Y13: 1000 | Z13: 3000 | AA13: 10000 | AB13: 50000 | AC13: 100000 | AD13: 0.005 | AE13: 0.0038 | AF13: 0.0033 | AG13: 0.0029 | AH13: 0.0028 | AI13: 0.0027 | AJ13: https://www.lcsc.com/product-detail/C15195.html (read 2026-10-14)
A14: 6 | B14: C12,C14,C17,C18 | C14: 1uF | D14: C_0402_1005Metric | E14: C52923 | F14: CL05A105KA5NQNC | G14: Samsung Electro-Mechanics | H14: 1uF 25V X5R 0402 | I14: 1 uF 25 V capacitors for supply decoupling (C12, C14, C17, C18). | J14: =LEN(B14)-LEN(SUBSTITUTE(B14,",",""))+1 -> 4 | K14: 2 | L14: Basic | M14: JLC page | N14: 598000 | O14: OK | P14: p0402 | Q14: =INDEX($C$52:$C$55,MATCH(P14,$B$52:$B$55,0)) -> 10 | R14: =J14*$C$5+Q14 -> 18 | S14: =INDEX($AD14:$AI14,MAX(1,COUNTIF($X14:$AC14,"<="&R14))) -> 0.0085 | T14: =R14*S14 -> 0.153 | U14: =J14*$C$6+Q14 -> 30 | V14: =INDEX($AD14:$AI14,MAX(1,COUNTIF($X14:$AC14,"<="&U14))) -> 0.0085 | W14: =U14*V14 -> 0.255 | X14: 50 | Y14: 500 | Z14: 1500 | AA14: 10000 | AB14: 20000 | AC14: 50000 | AD14: 0.0085 | AE14: 0.0067 | AF14: 0.0059 | AG14: 0.0053 | AH14: 0.005 | AI14: 0.0049 | AJ14: https://www.lcsc.com/product-detail/C52923.html (read 2026-10-14)
A15: 7 | B15: C7,C10,C16,C19,C20 | C15: 100nF | D15: C_0402_1005Metric | E15: C1525 | F15: CL05B104KO5NNNC | G15: Samsung Electro-Mechanics | H15: 100nF 16V X7R 0402 | I15: 100 nF capacitors: one next to each chip's supply pin (C7, C10, C16, C19, C20). | J15: =LEN(B15)-LEN(SUBSTITUTE(B15,",",""))+1 -> 5 | K15: 2 | L15: Basic | M15: JLC page | N15: 0 | O15: LCSC retail shows OUT OF STOCK, but the JLC basic-parts list shows 23,496,493 pcs (read 2026-10-14), so JLC can assemble it. | P15: p0402 | Q15: =INDEX($C$52:$C$55,MATCH(P15,$B$52:$B$55,0)) -> 10 | R15: =J15*$C$5+Q15 -> 20 | S15: =INDEX($AD15:$AI15,MAX(1,COUNTIF($X15:$AC15,"<="&R15))) -> 0.0046 | T15: =R15*S15 -> 0.092 | U15: =J15*$C$6+Q15 -> 35 | V15: =INDEX($AD15:$AI15,MAX(1,COUNTIF($X15:$AC15,"<="&U15))) -> 0.0046 | W15: =U15*V15 -> 0.161 | X15: 100 | Y15: 1000 | Z15: 3000 | AA15: 10000 | AB15: 50000 | AC15: 100000 | AD15: 0.0046 | AE15: 0.0035 | AF15: 0.003 | AG15: 0.0026 | AH15: 0.0025 | AI15: 0.0024 | AJ15: https://www.lcsc.com/product-detail/C1525.html (read 2026-10-14)
A16: 8 | B16: D1 | C16: ESD5Z5.0T1G | D16: D_SOD-523 | E16: C82044 | F16: ESD5Z5.0T1G | G16: onsemi | H16: 5 V unidirectional TVS (VBUS), SOD-523 | I16: D1: protects the board from static / voltage spikes on the USB 5 V line. | J16: =LEN(B16)-LEN(SUBSTITUTE(B16,",",""))+1 -> 1 | K16: 2 | L16: Extended | M16: JLC page | N16: 370780 | O16: OK | P16: semi | Q16: =INDEX($C$52:$C$55,MATCH(P16,$B$52:$B$55,0)) -> 2 | R16: =J16*$C$5+Q16 -> 4 | S16: =INDEX($AD16:$AI16,MAX(1,COUNTIF($X16:$AC16,"<="&R16))) -> 0.0371 | T16: =R16*S16 -> 0.1484 | U16: =J16*$C$6+Q16 -> 7 | V16: =INDEX($AD16:$AI16,MAX(1,COUNTIF($X16:$AC16,"<="&U16))) -> 0.0371 | W16: =U16*V16 -> 0.2597 | X16: 20 | Y16: 200 | Z16: 600 | AA16: 3000 | AB16: 9000 | AC16: 21000 | AD16: 0.0371 | AE16: 0.029 | AF16: 0.0245 | AG16: 0.0204 | AH16: 0.0181 | AI16: 0.0168 | AJ16: https://www.lcsc.com/product-detail/C82044.html (read 2026-10-14)
A17: 9 | B17: J1 | C17: TYPE-C-31-M-12 | D17: USB_C_Receptacle_HRO_TYPE-C-31-M-12 | E17: C165948 | F17: TYPE-C-31-M-12 | G17: Korean Hroparts Elec | H17: USB-C 16P receptacle (USB 2.0 data), SMD + 4 shell legs | I17: J1: USB-C socket (charging and data). 16 signal pads + 4 shell legs = 20 joints. | J17: =LEN(B17)-LEN(SUBSTITUTE(B17,",",""))+1 -> 1 | K17: 20 | L17: Extended | M17: JLC page | N17: 375745 | O17: OK | P17: mod | Q17: =INDEX($C$52:$C$55,MATCH(P17,$B$52:$B$55,0)) -> 1 | R17: =J17*$C$5+Q17 -> 3 | S17: =INDEX($AD17:$AI17,MAX(1,COUNTIF($X17:$AC17,"<="&R17))) -> 0.1729 | T17: =R17*S17 -> 0.5187 | U17: =J17*$C$6+Q17 -> 6 | V17: =INDEX($AD17:$AI17,MAX(1,COUNTIF($X17:$AC17,"<="&U17))) -> 0.1729 | W17: =U17*V17 -> 1.0374 | X17: 5 | Y17: 50 | Z17: 150 | AA17: 1000 | AB17: 2000 | AC17: 5000 | AD17: 0.1729 | AE17: 0.1365 | AF17: 0.1187 | AG17: 0.0963 | AH17: 0.092 | AI17: 0.0894 | AJ17: https://www.lcsc.com/product-detail/C165948.html (read 2026-10-14)
A18: 10 | B18: L1 | C18: 1uH | D18: L_Changjiang_FNR4020S | E18: C602028 | F18: FHD4020S-1R0MT | G18: cjiang | H18: 1 uH 4x4 mm, Isat 11 A, 23 mOhm (cjiang FHD4020S-1R0MT) | I18: L1: 1 uH power inductor of the buck converter U2 (LED driver). | J18: =LEN(B18)-LEN(SUBSTITUTE(B18,",",""))+1 -> 1 | K18: 2 | L18: Extended | M18: JLC page | N18: 8210 | O18: OK | P18: mod | Q18: =INDEX($C$52:$C$55,MATCH(P18,$B$52:$B$55,0)) -> 1 | R18: =J18*$C$5+Q18 -> 3 | S18: =INDEX($AD18:$AI18,MAX(1,COUNTIF($X18:$AC18,"<="&R18))) -> 0.1102 | T18: =R18*S18 -> 0.3306 | U18: =J18*$C$6+Q18 -> 6 | V18: =INDEX($AD18:$AI18,MAX(1,COUNTIF($X18:$AC18,"<="&U18))) -> 0.1102 | W18: =U18*V18 -> 0.6612 | X18: 10 | Y18: 100 | Z18: 300 | AA18: 3000 | AB18: 6000 | AC18: 9000 | AD18: 0.1102 | AE18: 0.086 | AF18: 0.0726 | AG18: 0.0645 | AH18: 0.0575 | AI18: 0.0538 | AJ18: https://www.lcsc.com/product-detail/C602028.html (read 2026-10-14)
A19: 11 | B19: LED3,LED4 | C19: NH-B1010RGBT-HF | D19: LED_RGB_1010_NH-B1010RGBT | E19: C2874113 | F19: NH-B1010RGBT-HF | G19: NATIONSTAR | H19: ring RGB LED 1x1 mm, common anode (pin 1), bottom side, emits into the light pipe | I19: LED3, LED4: the two RGB ring LEDs (1 x 1 mm, 4 pads under the package) that light the ring around the main button. | J19: =LEN(B19)-LEN(SUBSTITUTE(B19,",",""))+1 -> 2 | K19: 4 | L19: Extended | M19: JLC page | N19: 345020 | O19: OK | P19: semi | Q19: =INDEX($C$52:$C$55,MATCH(P19,$B$52:$B$55,0)) -> 2 | R19: =J19*$C$5+Q19 -> 6 | S19: =INDEX($AD19:$AI19,MAX(1,COUNTIF($X19:$AC19,"<="&R19))) -> 0.0081 | T19: =R19*S19 -> 0.0486 | U19: =J19*$C$6+Q19 -> 12 | V19: =INDEX($AD19:$AI19,MAX(1,COUNTIF($X19:$AC19,"<="&U19))) -> 0.0081 | W19: =U19*V19 -> 0.0972 | X19: 20 | Y19: 200 | Z19: 600 | AA19: 2000 | AB19: 10000 | AC19: 20000 | AD19: 0.0081 | AE19: 0.0072 | AF19: 0.0068 | AG19: 0.0065 | AH19: 0.0063 | AI19: 0.0053 | AJ19: https://www.lcsc.com/product-detail/C2874113.html (read 2026-10-14)
A20: 12 | B20: Q1 | C20: AO3401A | D20: SOT-23 | E20: C15127 | F20: AO3401A | G20: AOS | H20: P-MOSFET laser load switch | I20: Q1: P-channel MOSFET, the on/off switch of the laser. | J20: =LEN(B20)-LEN(SUBSTITUTE(B20,",",""))+1 -> 1 | K20: 3 | L20: Basic | M20: JLC page | N20: 164910 | O20: OK | P20: semi | Q20: =INDEX($C$52:$C$55,MATCH(P20,$B$52:$B$55,0)) -> 2 | R20: =J20*$C$5+Q20 -> 4 | S20: =INDEX($AD20:$AI20,MAX(1,COUNTIF($X20:$AC20,"<="&R20))) -> 0.1026 | T20: =R20*S20 -> 0.4104 | U20: =J20*$C$6+Q20 -> 7 | V20: =INDEX($AD20:$AI20,MAX(1,COUNTIF($X20:$AC20,"<="&U20))) -> 0.1026 | W20: =U20*V20 -> 0.7182 | X20: 5 | Y20: 50 | Z20: 150 | AA20: 500 | AB20: 3000 | AC20: 6000 | AD20: 0.1026 | AE20: 0.0829 | AF20: 0.0728 | AG20: 0.0644 | AH20: 0.0615 | AI20: 0.0596 | AJ20: https://www.lcsc.com/product-detail/C15127.html (read 2026-10-14)
A21: 13 | B21: Q2,Q4,Q5 | C21: 2N7002W | D21: SOT-323_SC-70 | E21: C5224240 | F21: 2N7002W-7-F-ES | G21: ElecSuper | H21: Q2: N-MOSFET current sink into FB (SOT-323); Q4: N-MOSFET (SOT-323): 3.3 V LASER_ON -> pulls the Q1 gate path low; Q5: VBUS-edge reset (SOT-323): pulls EN low for ~0.1 s when USB is plugged in | I21: Q2, Q4, Q5: small N-channel MOSFET switches (LED current sink, laser gate, reset pulse). | J21: =LEN(B21)-LEN(SUBSTITUTE(B21,",",""))+1 -> 3 | K21: 3 | L21: Extended | M21: JLC page | N21: 17000 | O21: OK | P21: semi | Q21: =INDEX($C$52:$C$55,MATCH(P21,$B$52:$B$55,0)) -> 2 | R21: =J21*$C$5+Q21 -> 8 | S21: =INDEX($AD21:$AI21,MAX(1,COUNTIF($X21:$AC21,"<="&R21))) -> 0.0224 | T21: =R21*S21 -> 0.1792 | U21: =J21*$C$6+Q21 -> 17 | V21: =INDEX($AD21:$AI21,MAX(1,COUNTIF($X21:$AC21,"<="&U21))) -> 0.0224 | W21: =U21*V21 -> 0.3808 | X21: 50 | Y21: 500 | Z21: 3000 | AA21: 6000 | AB21: 24000 | AC21: 51000 | AD21: 0.0224 | AE21: 0.017 | AF21: 0.0141 | AG21: 0.0123 | AH21: 0.0108 | AI21: 0.0099 | AJ21: https://www.lcsc.com/product-detail/C5224240.html (read 2026-10-14)
A22: 14 | B22: R1,R2 | C22: 5.1k | D22: R_0402_1005Metric | E22: C25905 | F22: 0402WGF5101TCE | G22: UNI-ROYAL | H22: 5.1k 1% 0402 resistor | I22: R1, R2: 5.1 k resistors on the USB-C CC pins (tell a charger to supply 5 V). | J22: =LEN(B22)-LEN(SUBSTITUTE(B22,",",""))+1 -> 2 | K22: 2 | L22: Basic | M22: JLC page | N22: 2302500 | O22: OK | P22: p0402 | Q22: =INDEX($C$52:$C$55,MATCH(P22,$B$52:$B$55,0)) -> 10 | R22: =J22*$C$5+Q22 -> 14 | S22: =INDEX($AD22:$AI22,MAX(1,COUNTIF($X22:$AC22,"<="&R22))) -> 0.0024 | T22: =R22*S22 -> 0.0336 | U22: =J22*$C$6+Q22 -> 20 | V22: =INDEX($AD22:$AI22,MAX(1,COUNTIF($X22:$AC22,"<="&U22))) -> 0.0024 | W22: =U22*V22 -> 0.048 | X22: 100 | Y22: 1000 | Z22: 3000 | AA22: 10000 | AB22: 50000 | AD22: 0.0024 | AE22: 0.0019 | AF22: 0.0015 | AG22: 0.0014 | AH22: 0.0012 | AJ22: https://www.lcsc.com/product-detail/C25905.html (read 2026-10-14)
A23: 15 | B23: R3 | C23: 3.3k | D23: R_0402_1005Metric | E23: C25890 | F23: 0402WGF3301TCE | G23: UNI-ROYAL | H23: 3.3k 1% 0402 resistor | I23: R3: 3.3 k resistor, sets the battery charge current (about 280 mA). | J23: =LEN(B23)-LEN(SUBSTITUTE(B23,",",""))+1 -> 1 | K23: 2 | L23: Basic | M23: JLC page | N23: 867600 | O23: OK | P23: p0402 | Q23: =INDEX($C$52:$C$55,MATCH(P23,$B$52:$B$55,0)) -> 10 | R23: =J23*$C$5+Q23 -> 12 | S23: =INDEX($AD23:$AI23,MAX(1,COUNTIF($X23:$AC23,"<="&R23))) -> 0.0036 | T23: =R23*S23 -> 0.0432 | U23: =J23*$C$6+Q23 -> 15 | V23: =INDEX($AD23:$AI23,MAX(1,COUNTIF($X23:$AC23,"<="&U23))) -> 0.0036 | W23: =U23*V23 -> 0.054 | X23: 100 | Y23: 1000 | Z23: 3000 | AA23: 10000 | AB23: 50000 | AD23: 0.0036 | AE23: 0.0027 | AF23: 0.0023 | AG23: 0.002 | AH23: 0.0018 | AJ23: https://www.lcsc.com/product-detail/C25890.html (read 2026-10-14)
A24: 16 | B24: R10 | C24: 200k | D24: R_0402_1005Metric | E24: C25764 | F24: 0402WGF2003TCE | G24: UNI-ROYAL | H24: 200k 1% 0402 resistor | I24: R10: 200 k resistor (voltage divider of the buck converter). | J24: =LEN(B24)-LEN(SUBSTITUTE(B24,",",""))+1 -> 1 | K24: 2 | L24: Basic | M24: JLC page | N24: 1520700 | O24: OK | P24: p0402 | Q24: =INDEX($C$52:$C$55,MATCH(P24,$B$52:$B$55,0)) -> 10 | R24: =J24*$C$5+Q24 -> 12 | S24: =INDEX($AD24:$AI24,MAX(1,COUNTIF($X24:$AC24,"<="&R24))) -> 0.0018 | T24: =R24*S24 -> 0.0216 | U24: =J24*$C$6+Q24 -> 15 | V24: =INDEX($AD24:$AI24,MAX(1,COUNTIF($X24:$AC24,"<="&U24))) -> 0.0018 | W24: =U24*V24 -> 0.027 | X24: 100 | Y24: 1000 | Z24: 3000 | AA24: 10000 | AB24: 50000 | AD24: 0.0018 | AE24: 0.0014 | AF24: 0.0011 | AG24: 0.001 | AH24: 0.0009 | AJ24: https://www.lcsc.com/product-detail/C25764.html (read 2026-10-14)
A25: 17 | B25: R12 | C25: 47k | D25: R_0402_1005Metric | E25: C25792 | F25: 0402WGF4702TCE | G25: UNI-ROYAL | H25: 47k 1% 0402 resistor | I25: R12: 47 k resistor. | J25: =LEN(B25)-LEN(SUBSTITUTE(B25,",",""))+1 -> 1 | K25: 2 | L25: Basic | M25: JLC page | N25: 3114700 | O25: OK | P25: p0402 | Q25: =INDEX($C$52:$C$55,MATCH(P25,$B$52:$B$55,0)) -> 10 | R25: =J25*$C$5+Q25 -> 12 | S25: =INDEX($AD25:$AI25,MAX(1,COUNTIF($X25:$AC25,"<="&R25))) -> 0.0026 | T25: =R25*S25 -> 0.0312 | U25: =J25*$C$6+Q25 -> 15 | V25: =INDEX($AD25:$AI25,MAX(1,COUNTIF($X25:$AC25,"<="&U25))) -> 0.0026 | W25: =U25*V25 -> 0.039 | X25: 100 | Y25: 1000 | Z25: 3000 | AA25: 10000 | AB25: 50000 | AD25: 0.0026 | AE25: 0.002 | AF25: 0.0017 | AG25: 0.0015 | AH25: 0.0013 | AJ25: https://www.lcsc.com/product-detail/C25792.html (read 2026-10-14)
A26: 18 | B26: R8,R9,R13,R18,R21,R22 | C26: 10k | D26: R_0402_1005Metric | E26: C25744 | F26: 0402WGF1002TCE | G26: UNI-ROYAL | H26: 10k 1% 0402 resistor | I26: 10 k resistors: pull-ups / pull-downs (R8, R9, R13, R18, R21, R22). | J26: =LEN(B26)-LEN(SUBSTITUTE(B26,",",""))+1 -> 6 | K26: 2 | L26: Basic | M26: JLC page | N26: 2846900 | O26: OK | P26: p0402 | Q26: =INDEX($C$52:$C$55,MATCH(P26,$B$52:$B$55,0)) -> 10 | R26: =J26*$C$5+Q26 -> 22 | S26: =INDEX($AD26:$AI26,MAX(1,COUNTIF($X26:$AC26,"<="&R26))) -> 0.0033 | T26: =R26*S26 -> 0.0726 | U26: =J26*$C$6+Q26 -> 40 | V26: =INDEX($AD26:$AI26,MAX(1,COUNTIF($X26:$AC26,"<="&U26))) -> 0.0033 | W26: =U26*V26 -> 0.132 | X26: 100 | Y26: 1000 | Z26: 3000 | AA26: 10000 | AB26: 50000 | AD26: 0.0033 | AE26: 0.0026 | AF26: 0.0022 | AG26: 0.0021 | AH26: 0.0017 | AJ26: https://www.lcsc.com/product-detail/C25744.html (read 2026-10-14)
A27: 19 | B27: R14,R31 | C27: 2.2k | D27: R_0402_1005Metric | E27: C25879 | F27: 0402WGF2201TCE | G27: UNI-ROYAL | H27: 2.2k 1% 0402 resistor | I27: R14: 2.2 k resistor (LED-current loop). R31: 2.2 k resistor of the button ladder (previous button). | J27: =LEN(B27)-LEN(SUBSTITUTE(B27,",",""))+1 -> 2 | K27: 2 | L27: Basic | M27: JLC page | N27: 586000 | O27: OK | P27: p0402 | Q27: =INDEX($C$52:$C$55,MATCH(P27,$B$52:$B$55,0)) -> 10 | R27: =J27*$C$5+Q27 -> 14 | S27: =INDEX($AD27:$AI27,MAX(1,COUNTIF($X27:$AC27,"<="&R27))) -> 0.0018 | T27: =R27*S27 -> 0.0252 | U27: =J27*$C$6+Q27 -> 20 | V27: =INDEX($AD27:$AI27,MAX(1,COUNTIF($X27:$AC27,"<="&U27))) -> 0.0018 | W27: =U27*V27 -> 0.036 | X27: 100 | Y27: 1000 | Z27: 3000 | AA27: 50000 | AD27: 0.0018 | AE27: 0.0013 | AF27: 0.0011 | AG27: 0.0009 | AJ27: https://www.lcsc.com/product-detail/C25879.html (read 2026-10-14)
A28: 20 | B28: R16 | C28: 2k | D28: R_0402_1005Metric | E28: C4109 | F28: 0402WGF2001TCE | G28: UNI-ROYAL | H28: 2k 1% 0402 resistor | I28: R16: 2 k resistor. | J28: =LEN(B28)-LEN(SUBSTITUTE(B28,",",""))+1 -> 1 | K28: 2 | L28: Basic | M28: JLC page | N28: 5789500 | O28: OK | P28: p0402 | Q28: =INDEX($C$52:$C$55,MATCH(P28,$B$52:$B$55,0)) -> 10 | R28: =J28*$C$5+Q28 -> 12 | S28: =INDEX($AD28:$AI28,MAX(1,COUNTIF($X28:$AC28,"<="&R28))) -> 0.0026 | T28: =R28*S28 -> 0.0312 | U28: =J28*$C$6+Q28 -> 15 | V28: =INDEX($AD28:$AI28,MAX(1,COUNTIF($X28:$AC28,"<="&U28))) -> 0.0026 | W28: =U28*V28 -> 0.039 | X28: 100 | Y28: 1000 | Z28: 3000 | AA28: 10000 | AB28: 50000 | AD28: 0.0026 | AE28: 0.002 | AF28: 0.0016 | AG28: 0.0015 | AH28: 0.0012 | AJ28: https://www.lcsc.com/product-detail/C4109.html (read 2026-10-14)
A29: 21 | B29: R19,R30 | C29: 1k | D29: R_0402_1005Metric | E29: C11702 | F29: 0402WGF1001TCE | G29: UNI-ROYAL | H29: 1k 1% 0402 resistor | I29: R19: 1 k resistor (laser gate). R30: 1 k resistor of the button ladder (next button). | J29: =LEN(B29)-LEN(SUBSTITUTE(B29,",",""))+1 -> 2 | K29: 2 | L29: Basic | M29: JLC page | N29: 0 | O29: LCSC retail shows OUT OF STOCK; JLC lists it as Basic - check the JLC stock at BOM upload. | P29: p0402 | Q29: =INDEX($C$52:$C$55,MATCH(P29,$B$52:$B$55,0)) -> 10 | R29: =J29*$C$5+Q29 -> 14 | S29: =INDEX($AD29:$AI29,MAX(1,COUNTIF($X29:$AC29,"<="&R29))) -> 0.0031 | T29: =R29*S29 -> 0.0434 | U29: =J29*$C$6+Q29 -> 20 | V29: =INDEX($AD29:$AI29,MAX(1,COUNTIF($X29:$AC29,"<="&U29))) -> 0.0031 | W29: =U29*V29 -> 0.062 | X29: 100 | Y29: 1000 | Z29: 3000 | AA29: 10000 | AB29: 50000 | AD29: 0.0031 | AE29: 0.0024 | AF29: 0.002 | AG29: 0.0018 | AH29: 0.0016 | AJ29: https://www.lcsc.com/product-detail/C11702.html (read 2026-10-14)
A30: 22 | B30: R23,R32 | C30: 330Ω | D30: R_0402_1005Metric | E30: C25104 | F30: 0402WGF3300TCE | G30: UNI-ROYAL | H30: 330 1% 0402 resistor | I30: R23, R32: 330 ohm resistors (red leg of the two ring LEDs). | J30: =LEN(B30)-LEN(SUBSTITUTE(B30,",",""))+1 -> 2 | K30: 2 | L30: Basic | M30: JLC page | N30: unknown | O30: ESTIMATE, page not read: JLCPCB and LCSC pages of C25104 could not be read on 2026-10-18. Tiers copied from the sibling 5.1 k resistor C25905 (read 2026-10-14); part number inferred from the UNI-ROYAL naming; library type 'Basic' assumed (same series as the other Basic 0402 resistors). Stock unknown. | P30: p0402 | Q30: =INDEX($C$52:$C$55,MATCH(P30,$B$52:$B$55,0)) -> 10 | R30: =J30*$C$5+Q30 -> 14 | S30: =INDEX($AD30:$AI30,MAX(1,COUNTIF($X30:$AC30,"<="&R30))) -> 0.0024 | T30: =R30*S30 -> 0.0336 | U30: =J30*$C$6+Q30 -> 20 | V30: =INDEX($AD30:$AI30,MAX(1,COUNTIF($X30:$AC30,"<="&U30))) -> 0.0024 | W30: =U30*V30 -> 0.048 | X30: 100 | Y30: 1000 | Z30: 3000 | AA30: 10000 | AB30: 50000 | AD30: 0.0024 | AE30: 0.0019 | AF30: 0.0015 | AG30: 0.0014 | AH30: 0.0012 | AJ30: ESTIMATE - LCSC and JLCPCB pages of C25104 could not be read on 2026-10-18. Tiers of the sibling C25905 (LCSC, read 2026-10-14).
A31: 23 | B31: R24,R25,R33,R34 | C31: 100Ω | D31: R_0402_1005Metric | E31: C25076 | F31: 0402WGF1000TCE | G31: UNI-ROYAL | H31: 100 1% 0402 resistor | I31: R24, R25, R33, R34: 100 ohm resistors (green and blue leg of each ring LED). | J31: =LEN(B31)-LEN(SUBSTITUTE(B31,",",""))+1 -> 4 | K31: 2 | L31: Basic | M31: JLC page | N31: 4360400 | O31: OK | P31: p0402 | Q31: =INDEX($C$52:$C$55,MATCH(P31,$B$52:$B$55,0)) -> 10 | R31: =J31*$C$5+Q31 -> 18 | S31: =INDEX($AD31:$AI31,MAX(1,COUNTIF($X31:$AC31,"<="&R31))) -> 0.0013 | T31: =R31*S31 -> 0.0234 | U31: =J31*$C$6+Q31 -> 30 | V31: =INDEX($AD31:$AI31,MAX(1,COUNTIF($X31:$AC31,"<="&U31))) -> 0.0013 | W31: =U31*V31 -> 0.039 | X31: 100 | Y31: 1000 | Z31: 3000 | AA31: 10000 | AD31: 0.0013 | AE31: 0.001 | AF31: 0.0009 | AG31: 0.0008 | AJ31: https://www.lcsc.com/product-detail/C25076.html (read 2026-10-14)
A32: 24 | B32: R27,R28 | C32: 1M | D32: R_0402_1005Metric | E32: C26083 | F32: 0402WGF1004TCE | G32: UNI-ROYAL | H32: 1M 1% 0402 resistor | I32: R27, R28: 1 M resistors. | J32: =LEN(B32)-LEN(SUBSTITUTE(B32,",",""))+1 -> 2 | K32: 2 | L32: Basic | M32: JLC page | N32: 541000 | O32: OK | P32: p0402 | Q32: =INDEX($C$52:$C$55,MATCH(P32,$B$52:$B$55,0)) -> 10 | R32: =J32*$C$5+Q32 -> 14 | S32: =INDEX($AD32:$AI32,MAX(1,COUNTIF($X32:$AC32,"<="&R32))) -> 0.0024 | T32: =R32*S32 -> 0.0336 | U32: =J32*$C$6+Q32 -> 20 | V32: =INDEX($AD32:$AI32,MAX(1,COUNTIF($X32:$AC32,"<="&U32))) -> 0.0024 | W32: =U32*V32 -> 0.048 | X32: 100 | Y32: 1000 | Z32: 3000 | AA32: 10000 | AB32: 50000 | AD32: 0.0024 | AE32: 0.0018 | AF32: 0.0016 | AG32: 0.0014 | AH32: 0.0011 | AJ32: https://www.lcsc.com/product-detail/C26083.html (read 2026-10-14)
A33: 25 | B33: R7,R11,R15,R17,R20,R26,R29 | C33: 100k | D33: R_0402_1005Metric | E33: C25741 | F33: 0402WGF1003TCE | G33: UNI-ROYAL | H33: 100k 1% 0402 resistor | I33: 100 k resistors: pull-ups / dividers (7 of them). | J33: =LEN(B33)-LEN(SUBSTITUTE(B33,",",""))+1 -> 7 | K33: 2 | L33: Basic | M33: JLC page | N33: 3791500 | O33: OK | P33: p0402 | Q33: =INDEX($C$52:$C$55,MATCH(P33,$B$52:$B$55,0)) -> 10 | R33: =J33*$C$5+Q33 -> 24 | S33: =INDEX($AD33:$AI33,MAX(1,COUNTIF($X33:$AC33,"<="&R33))) -> 0.0015 | T33: =R33*S33 -> 0.036 | U33: =J33*$C$6+Q33 -> 45 | V33: =INDEX($AD33:$AI33,MAX(1,COUNTIF($X33:$AC33,"<="&U33))) -> 0.0015 | W33: =U33*V33 -> 0.0675 | X33: 100 | Y33: 1000 | Z33: 3000 | AA33: 10000 | AB33: 50000 | AD33: 0.0015 | AE33: 0.0012 | AF33: 0.001 | AG33: 0.0009 | AH33: 0.0008 | AJ33: https://www.lcsc.com/product-detail/C25741.html (read 2026-10-14)
A34: 26 | B34: RS1 | C34: 20mΩ | D34: R_0805_2012Metric | E34: C92740 | F34: MS05W2F200MT5E | G34: UNI-ROYAL | H34: 20 mOhm 1 % 0.5 W 0805 current sense (Kelvin) | I34: RS1: 20 milliohm current-sense resistor (measures the LED current). | J34: =LEN(B34)-LEN(SUBSTITUTE(B34,",",""))+1 -> 1 | K34: 2 | L34: Extended | M34: JLC page | N34: 4880 | O34: OK | P34: p0603 | Q34: =INDEX($C$52:$C$55,MATCH(P34,$B$52:$B$55,0)) -> 5 | R34: =J34*$C$5+Q34 -> 7 | S34: =INDEX($AD34:$AI34,MAX(1,COUNTIF($X34:$AC34,"<="&R34))) -> 0.0183 | T34: =R34*S34 -> 0.1281 | U34: =J34*$C$6+Q34 -> 10 | V34: =INDEX($AD34:$AI34,MAX(1,COUNTIF($X34:$AC34,"<="&U34))) -> 0.0183 | W34: =U34*V34 -> 0.183 | X34: 20 | Y34: 200 | Z34: 600 | AA34: 2000 | AD34: 0.0183 | AE34: 0.018 | AF34: 0.0177 | AG34: 0.0174 | AJ34: https://www.lcsc.com/product-detail/C92740.html (read 2026-10-14)
A35: 27 | B35: RT1 | C35: 100k B4250 | D35: R_0402_1005Metric | E35: C77130 | F35: NCP15WF104F03RC | G35: muRata | H35: NTC 100 k B25/50 4250 0402 (Murata NCP15WF104F03RC), PCB front edge | I35: RT1: 100 k NTC thermistor = temperature sensor at the front edge of the PCB. | J35: =LEN(B35)-LEN(SUBSTITUTE(B35,",",""))+1 -> 1 | K35: 2 | L35: Extended | M35: JLC page | N35: 298120 | O35: OK | P35: p0402 | Q35: =INDEX($C$52:$C$55,MATCH(P35,$B$52:$B$55,0)) -> 10 | R35: =J35*$C$5+Q35 -> 12 | S35: =INDEX($AD35:$AI35,MAX(1,COUNTIF($X35:$AC35,"<="&R35))) -> 0.0219 | T35: =R35*S35 -> 0.2628 | U35: =J35*$C$6+Q35 -> 15 | V35: =INDEX($AD35:$AI35,MAX(1,COUNTIF($X35:$AC35,"<="&U35))) -> 0.0219 | W35: =U35*V35 -> 0.3285 | X35: 20 | Y35: 200 | Z35: 600 | AA35: 2000 | AB35: 10000 | AC35: 20000 | AD35: 0.0219 | AE35: 0.0173 | AF35: 0.0147 | AG35: 0.0132 | AH35: 0.0119 | AI35: 0.0112 | AJ35: https://www.lcsc.com/product-detail/C77130.html (read 2026-10-14)
A36: 28 | B36: S2 | C36: MSK12C02 | D36: SW_SPDT_PCM12 | E36: C431540 | F36: MSK12C02 | G36: SHOU HAN | H36: SPDT slide switch, laser interlock (gate path only) | I36: S2: slide switch = the laser safety interlock. | J36: =LEN(B36)-LEN(SUBSTITUTE(B36,",",""))+1 -> 1 | K36: 7 | L36: Extended | M36: JLC page | N36: 170330 | O36: OK | P36: mod | Q36: =INDEX($C$52:$C$55,MATCH(P36,$B$52:$B$55,0)) -> 1 | R36: =J36*$C$5+Q36 -> 3 | S36: =INDEX($AD36:$AI36,MAX(1,COUNTIF($X36:$AC36,"<="&R36))) -> 0.0543 | T36: =R36*S36 -> 0.1629 | U36: =J36*$C$6+Q36 -> 6 | V36: =INDEX($AD36:$AI36,MAX(1,COUNTIF($X36:$AC36,"<="&U36))) -> 0.0543 | W36: =U36*V36 -> 0.3258 | X36: 10 | Y36: 100 | Z36: 300 | AA36: 3000 | AB36: 6000 | AC36: 9000 | AD36: 0.0543 | AE36: 0.0444 | AF36: 0.0394 | AG36: 0.0337 | AH36: 0.0323 | AI36: 0.0312 | AJ36: https://www.lcsc.com/product-detail/C431540.html (read 2026-10-14)
A37: 29 | B37: SW1,SW2,SW3 | C37: SKRKAEE020 | D37: SW_Push_SPST_NO_Alps_SKRK | E37: C115357 | F37: SKRKAEE020 | G37: ALPSALPINE | H37: SW1: main button: Alps top-push tact switch, 1.6 N, bottom side (ring centre); SW2: next button (>): Alps top-push tact switch, bottom side; SW3: previous button (<): Alps top-push tact switch, bottom side | I37: SW1, SW2, SW3: the three push buttons (main, next, previous). Alps top-push tact switch 3.9 x 2.9 x 2.0 mm, 1.6 N, 200k cycles, on the bottom side. | J37: =LEN(B37)-LEN(SUBSTITUTE(B37,",",""))+1 -> 3 | K37: 2 | L37: Extended | M37: JLC page | N37: unknown | O37: ESTIMATE, page not read: JLCPCB and LCSC pages of C115357 could not be read on 2026-10-18. Tiers = the sibling Alps SKRPABE010 (C115360) read on LCSC on 2026-10-16 (qty 10 $0.0759, qty 100 $0.0616). Stock unknown. Library type 'Extended' assumed (every Alps tact switch checked on JLCPCB is Extended). | P37: mod | Q37: =INDEX($C$52:$C$55,MATCH(P37,$B$52:$B$55,0)) -> 1 | R37: =J37*$C$5+Q37 -> 7 | S37: =INDEX($AD37:$AI37,MAX(1,COUNTIF($X37:$AC37,"<="&R37))) -> 0.0759 | T37: =R37*S37 -> 0.5313 | U37: =J37*$C$6+Q37 -> 16 | V37: =INDEX($AD37:$AI37,MAX(1,COUNTIF($X37:$AC37,"<="&U37))) -> 0.0759 | W37: =U37*V37 -> 1.2144 | X37: 10 | Y37: 100 | AD37: 0.0759 | AE37: 0.0616 | AJ37: ESTIMATE - LCSC and JLCPCB pages of C115357 could not be read on 2026-10-18. Tiers of the sibling C115360 (LCSC, read 2026-10-16): qty 10 $0.0759, qty 100 $0.0616.
A38: 30 | B38: U1 | C38: TP4057 | D38: SOT-23-6 | E38: C12044 | F38: TP4057-42-SOT26-R | G38: TOP POWER ASIC | H38: TP4057-42-SOT26-R 500 mA Li-ion linear charger (R3 3.3k = ~300 mA) | I38: U1: battery charger chip (500 mA linear Li-ion charger). | J38: =LEN(B38)-LEN(SUBSTITUTE(B38,",",""))+1 -> 1 | K38: 6 | L38: Extended | M38: JLC page | N38: 32025 | O38: OK | P38: semi | Q38: =INDEX($C$52:$C$55,MATCH(P38,$B$52:$B$55,0)) -> 2 | R38: =J38*$C$5+Q38 -> 4 | S38: =INDEX($AD38:$AI38,MAX(1,COUNTIF($X38:$AC38,"<="&R38))) -> 0.1426 | T38: =R38*S38 -> 0.5704 | U38: =J38*$C$6+Q38 -> 7 | V38: =INDEX($AD38:$AI38,MAX(1,COUNTIF($X38:$AC38,"<="&U38))) -> 0.1426 | W38: =U38*V38 -> 0.9982 | X38: 5 | Y38: 50 | Z38: 150 | AA38: 500 | AB38: 3000 | AC38: 6000 | AD38: 0.1426 | AE38: 0.1166 | AF38: 0.1036 | AG38: 0.0938 | AH38: 0.0761 | AI38: 0.0722 | AJ38: https://www.lcsc.com/product-detail/C12044.html (read 2026-10-14)
A39: 31 | B39: U2 | C39: TLV62585DRLR | D39: SOT-563 | E39: C485117 | F39: TLV62585DRLR | G39: Texas Instruments | H39: 3 A sync buck, 100 % duty mode, SOT-563 | I39: U2: 3 A buck converter that drives the LED. | J39: =LEN(B39)-LEN(SUBSTITUTE(B39,",",""))+1 -> 1 | K39: 6 | L39: Extended | M39: JLC page | N39: 925 | O39: LOW stock at LCSC (925 pcs) - fine for 5 boards, check at BOM upload. | P39: semi | Q39: =INDEX($C$52:$C$55,MATCH(P39,$B$52:$B$55,0)) -> 2 | R39: =J39*$C$5+Q39 -> 4 | S39: =INDEX($AD39:$AI39,MAX(1,COUNTIF($X39:$AC39,"<="&R39))) -> 0.261 | T39: =R39*S39 -> 1.044 | U39: =J39*$C$6+Q39 -> 7 | V39: =INDEX($AD39:$AI39,MAX(1,COUNTIF($X39:$AC39,"<="&U39))) -> 0.261 | W39: =U39*V39 -> 1.827 | X39: 5 | Y39: 50 | Z39: 150 | AA39: 500 | AB39: 3000 | AC39: 6000 | AD39: 0.261 | AE39: 0.2052 | AF39: 0.178 | AG39: 0.1537 | AH39: 0.147 | AI39: 0.143 | AJ39: https://www.lcsc.com/product-detail/C485117.html (read 2026-10-14)
A40: 32 | B40: U3 | C40: TLV333IDCKR | D40: SOT-353_SC-70-5 | E40: C181502 | F40: TLV333IDCKR | G40: Texas Instruments | H40: zero-drift op-amp SC-70-5 (DCK), powered from LED_EN | I40: U3: precision op-amp in the LED-current control loop. | J40: =LEN(B40)-LEN(SUBSTITUTE(B40,",",""))+1 -> 1 | K40: 5 | L40: Extended | M40: JLC page | N40: 18425 | O40: OK | P40: semi | Q40: =INDEX($C$52:$C$55,MATCH(P40,$B$52:$B$55,0)) -> 2 | R40: =J40*$C$5+Q40 -> 4 | S40: =INDEX($AD40:$AI40,MAX(1,COUNTIF($X40:$AC40,"<="&R40))) -> 0.3543 | T40: =R40*S40 -> 1.4172 | U40: =J40*$C$6+Q40 -> 7 | V40: =INDEX($AD40:$AI40,MAX(1,COUNTIF($X40:$AC40,"<="&U40))) -> 0.3543 | W40: =U40*V40 -> 2.4801 | X40: 5 | Y40: 50 | Z40: 150 | AA40: 500 | AB40: 3000 | AC40: 6000 | AD40: 0.3543 | AE40: 0.2788 | AF40: 0.2465 | AG40: 0.1927 | AH40: 0.1747 | AI40: 0.1639 | AJ40: https://www.lcsc.com/product-detail/C181502.html (read 2026-10-14)
A41: 33 | B41: U4 | C41: ESP32-C3-MINI-1-N4 | D41: ESP32-C3-MINI-1 | E41: C2838502 | F41: ESP32-C3-MINI-1-N4 | G41: Espressif | H41: ESP32-C3 BLE 5 / Wi-Fi module, 4 MB flash, PCB antenna (alt. -H4X C41349510) | I41: U4: the brain - ESP32-C3 module with Bluetooth LE / Wi-Fi, 4 MB flash and antenna. | J41: =LEN(B41)-LEN(SUBSTITUTE(B41,",",""))+1 -> 1 | K41: 53 | L41: Extended | M41: JLC page | N41: 8387 | O41: Marked NRND (not recommended for new designs) by Espressif; the successor ESP32-C3-MINI-1-H4X (C41349510) is the drop-in alternative if this one disappears. | P41: mod | Q41: =INDEX($C$52:$C$55,MATCH(P41,$B$52:$B$55,0)) -> 1 | R41: =J41*$C$5+Q41 -> 3 | S41: =INDEX($AD41:$AI41,MAX(1,COUNTIF($X41:$AC41,"<="&R41))) -> 3.0672 | T41: =R41*S41 -> 9.2016 | U41: =J41*$C$6+Q41 -> 6 | V41: =INDEX($AD41:$AI41,MAX(1,COUNTIF($X41:$AC41,"<="&U41))) -> 3.0672 | W41: =U41*V41 -> 18.4032 | X41: 1 | Y41: 10 | Z41: 30 | AA41: 100 | AB41: 650 | AC41: 1300 | AD41: 3.0672 | AE41: 2.7002 | AF41: 2.5127 | AG41: 2.1441 | AH41: 2.0536 | AI41: 2.0141 | AJ41: https://www.lcsc.com/product-detail/C2838502.html (read 2026-10-14)
...

Sheet Housing
A1: Housing - aluminium tray + lid and stainless caps (JLCCNC), resin print kit (JLC3DP)
A2: Tray and lid are CNC-milled from aluminium 6061-T6 with bead blast + black anodize and laser marking at JLCCNC. The three caps (cap_main x1, cap_slide x2 per light) are turned from SUS304 stainless steel and bead blasted, also at JLCCNC. The RF window insert, LED spacer ring, antenna spacer with floor plug, light-pipe tube and the resin copies of the three caps are printed in translucent SLA resin 8001 at JLC3DP as ONE print kit: seven parts joined by 1 mm sprues, which you cut apart at home. JLCCNC and JLC3DP show their real price only after you upload the files, and JLCCNC publishes no per-part price at all, so every price on this sheet is an ESTIMATE made from the volume, the bounding box and the finish with the method written below. When you have the instant quote, type it into the 'real quote' cells (sections 6, 7 and 8): the workbook then uses your number.
A3: Geometry source: cad/housing_interface.json (version 0.6) + cad/*.stl. Files to upload: order_files/2_JLCCNC/ (JLCCNC) and order_files/3_JLC3DP/ (JLC3DP); the JLCCNC drawings there are cad/FlashKa_tray_drawing.pdf, FlashKa_lid_drawing.pdf, FlashKa_cap_main_drawing.pdf and FlashKa_cap_slide_drawing.pdf renamed to the names of their STEP files (FlashKa_tray.pdf, FlashKa_lid.pdf, FlashKa_cap_main.pdf, FlashKa_cap_slide.pdf).
A5: 1. Parts and geometry (volumes from housing_interface.json 'volumes_mm3', for the print kit and the laser sleeve from their STL files; boxes from 'tray_bbox' and the STL files)
A6: Part | B6: Process | C6: Box X (mm) | D6: Box Y (mm) | E6: Box Z (mm) | F6: Volume (mm3) | G6: Mass (g) | H6: Per light | I6: Spare per order | J6: File (STEP / STL) | K6: Note
A7: Tray (main body, 94.4 x 20 x 16 mm) | B7: CNC aluminium | C7: 94.4 | D7: 20 | E7: 16 | F7: 8401.2 | G7: 22.68 | H7: 1 | I7: 0 | J7: order_files/2_JLCCNC/FlashKa_tray.step + FlashKa_tray.pdf | K7: 4 x M1.6 lid threads + 1 x M2 laser set-screw thread, window and laser bores, cell bay, three floor holes for the caps and the tube, floor RF window, lanyard slot, skin seams (frames and stringers), laser marking of 3 faces (bottom, -Y, +Y).
A8: Lid (90.2 x 20 x 5.2 mm) | B8: CNC aluminium | C8: 90.2 | D8: 20 | E8: 5.2 | F8: 2643.3 | G8: 7.14 | H8: 1 | I8: 0 | J8: order_files/2_JLCCNC/FlashKa_lid.step + FlashKa_lid.pdf | K8: 1.5 mm plate with two hold-down bosses (up to 5.2 mm tall), 0.6 mm rabbet lip, 4 countersunk holes, RF-window pocket, skin seams and the label field (laser marking of the lid face). Thin parts are harder to clamp, hence the factor 1.30.
A9: Main cap, stainless SUS304 (head dia 5.8, flange dia 6.6, 6.6 x 6.6 x 7 mm) | B9: CNC stainless | C9: 6.6 | D9: 6.6 | E9: 7 | F9: 108.9 | G9: 0.86 | H9: 1 | I9: 1 | J9: order_files/2_JLCCNC/FlashKa_cap_main.step + FlashKa_cap_main.pdf | K9: Turned part with a domed head, bead blasted, no coating. 1 per light + 1 spare. Tiny: JLCCNC may refuse it by size (see section 10); the resin main cap of the print kit is the fallback.
A10: Slide cap, stainless SUS304 (head dia 3.4, flange dia 5.0, 5 x 5 x 7 mm) | B10: CNC stainless | C10: 5 | D10: 5 | E10: 7 | F10: 40 | G10: 0.32 | H10: 2 | I10: 1 | J10: order_files/2_JLCCNC/FlashKa_cap_slide.step + FlashKa_cap_slide.pdf | K10: Same turned part for the next and the previous button, bead blasted. 2 per light + 1 spare. The resin slide caps of the print kit are the fallback.
A11: Print kit = the 7 resin parts below on 1 mm sprues (ONE part at JLC3DP) | B11: SLA resin | C11: 57.2 | D11: 16.8 | E11: 14.15 | F11: 1576.2 | G11: 1.8 | H11: 1 | I11: 1 | J11: order_files/3_JLC3DP/FlashKa_print_kit.stl | K11: What you order at JLC3DP: the RF window insert, LED spacer ring, antenna spacer with floor plug, light-pipe tube, resin main cap and 2 resin slide caps joined by 1 mm sprues, because the RF window insert alone is below JLC3DP's minimum build size (5 x 5 x 5 mm or 10 x 2 x 2 mm); the other parts ride along, so that one part, one minimum price and one customs line cover all seven. One kit per light + one spare kit. Volume and box are measured from the kit's own STL; you cut the parts apart at home with flush cutters.
A12: RF window insert - in the print kit | B12: SLA resin | C12: 8.4 | D12: 15.5 | E12: 1.7 | F12: 184.1 | G12: 0.21 | H12: 0 | I12: 0 | J12: cad/FlashKa_rf_window.stl (geometry only - not uploaded, it is in the kit) | K12: Included in the print kit (cut apart at home). Translucent resin lets the Bluetooth signal out; glued into the lid with epoxy. Flange 0.8 mm thick. Alone it is below the minimum build size: that is why it is printed in the kit.
A13: LED spacer ring - in the print kit | B13: SLA resin | C13: 2.4 | D13: 10.1 | E13: 10.1 | F13: 83.9 | G13: 0.1 | H13: 0 | I13: 0 | J13: cad/FlashKa_spacer_ring.stl (geometry only - not uploaded, it is in the kit) | K13: Included in the print kit (cut apart at home). Ring OD 10.1 / ID 7.2 mm between the LED board and the glass window.
A14: Antenna spacer with floor plug - in the print kit | B14: SLA resin | C14: 6 | D14: 16.8 | E14: 14.15 | F14: 926.8 | G14: 1.07 | H14: 0 | I14: 0 | J14: cad/FlashKa_antenna_spacer.stl (geometry only - not uploaded, it is in the kit) | K14: Included in the print kit (cut apart at home). Keeps the cells away from the ESP32 antenna; its plug closes the floor RF window.
A15: Light-pipe tube - in the print kit | B15: SLA resin | C15: 8.8 | D15: 8.8 | E15: 8.2 | F15: 178.1 | G15: 0.2 | H15: 0 | I15: 0 | J15: cad/FlashKa_tube.stl (geometry only - not uploaded, it is in the kit) | K15: Included in the print kit (cut apart at home). Carries the light of the two ring LEDs round the main cap; OD 8.4, rim 8.8 mm, glued into the counterbore of the floor (clear epoxy, not cyanoacrylate).
A16: Main cap in resin (fallback of the steel cap) - in the print kit | B16: SLA resin | C16: 6.6 | D16: 6.6 | E16: 7 | F16: 108.9 | G16: 0.13 | H16: 0 | I16: 0 | J16: cad/FlashKa_cap_main.stl (geometry only - not uploaded, it is in the kit) | K16: Included in the print kit (cut apart at home). Same geometry as the steel main cap: fit check, or the replacement if the steel cap is refused or not wanted.
A17: Slide cap in resin, 2 per kit (fallback of the steel caps) - in the print kit | B17: SLA resin | C17: 5 | D17: 5 | E17: 7 | F17: 40 | G17: 0.05 | H17: 0 | I17: 0 | J17: cad/FlashKa_cap_slide.stl (geometry only - not uploaded, it is in the kit) | K17: Included in the print kit (cut apart at home). Two identical caps in each kit (next and previous button), same geometry as the steel slide cap.
A18: Laser sleeve (optional, separate print) | B18: SLA resin | C18: 10 | D18: 6 | E18: 5.97 | F18: 110.9 | G18: 0.1 | H18: 0 | I18: 0 | J18: order_files/3_JLC3DP/FlashKa_laser_sleeve.stl | K18: ONLY if your laser module is 4.5 mm instead of 6.0 mm: set 'Per light' to 1. Not part of the kit: it is a separate STL (order_files/3_JLC3DP/FlashKa_laser_sleeve.stl) and big enough to be printed on its own.
A20: 2. JLCCNC estimate - method (all inputs are ESTIMATES; JLCCNC publishes no price list, https://jlccnc.com/blog/cnc-machining-cost-factors)
A21: Cost of one aluminium part = aluminium (stock block weight x price) + machining (minutes x rate x complexity) + threads + finish + laser marking. Stock block = bounding box + allowance on every side. Machining minutes = material to remove / removal rate + minutes for fine features (grooves, holes, pockets: section 4). Per order you also pay set-ups (each re-clamping of the part), the anodizing lot fee and the marking set-up once. Calibrated in v0.5 so that one tray + lid costs about the same as the v0.4 estimate (tray $31, lid $12) plus finish and set-ups; v0.6 keeps these inputs and changes only what the new design changes (sections 4 and 5).
